Workbook
Name MethodPointer: 49099728
Name MethodPointer: 170018840
Name MethodPointer: 166869040

Sheet Master Spreadsheet
A1: ID | B1: ECOA | C1: CV | D1: Treatment | E1: Date | F1: Notes
A2: 3.2 (C) | B2: ='10_29_24_RawData_Plate1'!G108 -> 0.146 | C2: 1.939 | D2: Overwinter | E2: 45625
A3: 3.3 (C) | B3: ='10_29_24_RawData_Plate1'!G110 -> 0.449 | C3: 24.306 | D3: Greenhouse | E3: 45625
A4: 7.2 (C) | B4: ='10_29_24_RawData_Plate1'!G112 -> 0.451 | C4: 6.351 | D4: Greenhouse | E4: 45625
A5: 14.5 (C) | B5: ='10_29_24_RawData_Plate1'!G114 -> 0.089 | C5: 38.546 | D5: Overwinter | E5: 45625
A6: 15.1 (C) | B6: ='10_29_24_RawData_Plate1'!G116 -> 0.043 | C6: 244.795 | D6: Greenhouse | E6: 45625
A7: 9.6 (C) | B7: ='10_29_24_RawData_Plate1'!G118 -> 0.151 | C7: 30.314 | D7: Overwinter | E7: 45625
A8: 5.4 (C) | B8: ='10_29_24_RawData_Plate1'!G120 -> 0.156 | C8: 37.715 | D8: Overwinter | E8: 45625
A9: 6.2(C) | B9: ='10_29_24_RawData_Plate1'!G122 -> 0.257 | C9: 13.237 | D9: Greenhouse | E9: 45625
A10: 5.2 (C) | B10: ='10_29_24_RawData_Plate1'!G124 -> 0.123 | C10: 8.711 | D10: Overwinter | E10: 45625
A11: 13.2 (C) | B11: ='10_29_24_RawData_Plate1'!G126 -> 0.298 | C11: 26.746 | D11: Greenhouse | E11: 45625
A12: 6.4 (C) | B12: ='10_29_24_RawData_Plate1'!G128 -> 0.137 | C12: 4.941 | D12: Overwinter | E12: 45625
A13: 12.2 (C) | B13: ='10_29_24_RawData_Plate1'!G130 -> 0.247 | C13: 2.121 | D13: Greenhouse | E13: 45625
A14: 5.5 (C) | B14: ='10_29_24_RawData_Plate1'!G132 -> 0.32 | C14: 36.225 | D14: Greenhouse | E14: 45625
A15: 13.1 (C) | B15: ='10_29_24_RawData_Plate1'!G134 -> 0.148 | C15: 9.365 | D15: Overwinter | E15: 45625
A16: 5.1 (C) | B16: ='10_29_24_RawData_Plate1'!G136 -> 0.397 | C16: 5.072 | D16: Greenhouse | E16: 45625
A17: 12.5 (C) | B17: ='10_29_24_RawData_Plate1'!G138 -> 0.199 | C17: 10.639 | D17: Overwinter | E17: 45625
A18: 10.6 (C) | B18: ='10_29_24_RawData_Plate1'!G140 -> 0.207 | C18: 7.699 | D18: Overwinter | E18: 45625
A19: 10.6 (C) | B19: ='10_29_24_RawData_Plate1'!G142 -> 0.047 | C19: 11.092 | D19: Overwinter | E19: 45625
A20: 10.1 (C) | B20: ='10_29_24_RawData_Plate1'!G144 -> 0.158 | C20: 45.862 | D20: Greenhouse | E20: 45625
A21: 7.3 (C) | B21: ='10_29_24_RawData_Plate1'!G146 -> 0.078 | C21: 26.701 | D21: Overwinter | E21: 45625
A22: 9.4 (C) | B22: ='10_29_24_RawData_Plate1'!G148 -> -0.111 | C22: -1.85 | D22: Greenhouse | E22: 45625
A23: 14.4 (C) | B23: ='10_29_24_RawData_Plate1'!G150 -> 0.173 | C23: 17.571 | D23: Greenhouse | E23: 45625
A24: 15.2 (C) | B24: ='10_29_24_RawData_Plate1'!G152 -> 0.096 | C24: 28.611 | D24: Overwinter | E24: 45625

Sheet 10_29_24_RawData_Plate1
A2: Software Version | B2: 2.09.1
A4: Experiment File Path: | B4: E:\GT_Metabolomics\ECOA_11_29_24_Plate1.xpt
A5: Protocol File Path: | B5: C:\Users\Public\Documents\Protocols\Schwartz_ECOA.prt
A6: Plate Number | B6: Plate 1
A7: Date | B7: 45625
A8: Time | B8: 0.92976852
A9: Reader Type: | B9: Cytation3
A10: Reader Serial Number: | B10: 13081218
A11: Reading Type | B11: Reader
A13: Procedure Details
A14: Plate Type | B14: 96 WELL PLATE
A15: Eject plate on completion
A16: Read | B16: Absorbance Endpoint
B17: Full Plate
B18: Wavelengths: 570
B19: Read Speed: Normal, Delay: 100 msec, Measurements/Data Point: 8
A21: Layout
C23: 1 | D23: 2 | E23: 3 | F23: 4 | G23: 5 | H23: 6 | I23: 7 | J23: 8 | K23: 9 | L23: 10 | M23: 11 | N23: 12
B24: A | C24: BLK | D24: SPL4 | E24: SPL7 | F24: SPL11 | G24: SPL15 | H24: SPL18 | O24: Well ID
B25: B | C25: BLK | D25: SPL4 | E25: SPL7 | F25: SPL11 | G25: SPL15 | H25: SPL18 | O25: Well ID
B26: C | C26: SPL1 | D26: SPL5 | E26: SPL8 | F26: SPL12 | G26: SPL16 | H26: SPL19 | I26: BLK | O26: Well ID
B27: D | C27: SPL1 | D27: SPL5 | E27: SPL8 | F27: SPL12 | G27: SPL16 | H27: SPL19 | I27: BLK | O27: Well ID
B28: E | C28: SPL2 | D28: BLK | E28: SPL9 | F28: SPL13 | G28: SPL17 | H28: SPL20 | I28: SPL22 | O28: Well ID
B29: F | C29: SPL2 | D29: BLK | E29: SPL9 | F29: SPL13 | G29: SPL17 | H29: SPL20 | I29: SPL22 | O29: Well ID
B30: G | C30: SPL3 | D30: SPL6 | E30: SPL10 | F30: SPL14 | G30: BLK | H30: SPL21 | I30: SPL23 | O30: Well ID
B31: H | C31: SPL3 | D31: SPL6 | E31: SPL10 | F31: SPL14 | G31: BLK | H31: SPL21 | I31: SPL23 | O31: Well ID
A33: 570
A34: Actual Temperature: | B34: 26.5
A35: Actual Temperature: | B35: 26.5
A36: Actual Temperature: | B36: 26.5
A37: Actual Temperature: | B37: 26.5
A38: Actual Temperature: | B38: 26.5
B40: Well ID | C40: Well | D40: 570 | E40: Count | F40: Mean | G40: Std Dev | H40: CV (%)
B41: BLK | C41: A1 | D41: 0.049 | E41: 8 | F41: 0.158 | G41: 0.213 | H41: 134.865
C42: B1 | D42: 0.045
C43: C7 | D43: 0.046
C44: D7 | D44: 0.047
C45: G5 | D45: 0.394
C46: H5 | D46: 0.591
C47: E2 | D47: 0.045
...

Sheet ECOA_10_10_24_RawData
A2: Software Version | B2: 2.09.1
A4: Experiment File Path: | B4: E:\GT_Metabolomics\2024_10_10_ECOA_Optimization.xpt
A5: Protocol File Path: | B5: C:\Users\Public\Documents\Protocols\Schwartz_ECOA.prt
A6: Plate Number | B6: Plate 1
A7: Date | B7: 45575
A8: Time | B8: 0.75822917
A9: Reader Type: | B9: Cytation3
A10: Reader Serial Number: | B10: 13081218
A11: Reading Type | B11: Reader
A13: Procedure Details
A14: Plate Type | B14: 96 WELL PLATE
A15: Eject plate on completion
A16: Read | B16: Absorbance Endpoint
B17: Random
B18: Wavelengths: 570
B19: Read Speed: Normal, Delay: 100 msec, Measurements/Data Point: 8
A21: Layout
C23: 1 | D23: 2 | E23: 3 | F23: 4 | G23: 5 | H23: 6 | I23: 7 | J23: 8 | K23: 9 | L23: 10 | M23: 11 | N23: 12
B24: A | C24: BLK | D24: STD4 | E24: SPL4 | F24: SPL8 | O24: Well ID
D25: 1000 | O25: Conc/Dil
B26: B | C26: BLK | D26: STD4 | E26: SPL4 | F26: SPL8 | O26: Well ID
D27: 1000 | O27: Conc/Dil
B28: C | C28: STD1 | D28: SPL1 | E28: SPL5 | F28: SPL9 | O28: Well ID
C29: 0 | O29: Conc/Dil
B30: D | C30: STD1 | D30: SPL1 | E30: SPL5 | F30: SPL9 | O30: Well ID
C31: 0 | O31: Conc/Dil
B32: E | C32: STD2 | D32: SPL2 | E32: SPL6 | F32: SPL10 | O32: Well ID
C33: 300 | O33: Conc/Dil
B34: F | C34: STD2 | D34: SPL2 | E34: SPL6 | F34: SPL10 | O34: Well ID
C35: 300 | O35: Conc/Dil
B36: G | C36: STD3 | D36: SPL3 | E36: SPL7 | O36: Well ID
C37: 600 | O37: Conc/Dil
B38: H | C38: STD3 | D38: SPL3 | E38: SPL7 | O38: Well ID
C39: 600 | O39: Conc/Dil
A41: Results
A42: Actual Temperature: | B42: 23.3
B44: Well ID | C44: Well | D44: Conc/Dil | E44: 570 | F44: Blank 570 | G44: Count | H44: Mean | I44: Std Dev | J44: CV (%)
B45: BLK | C45: A1 | E45: 0.048 | F45: 0.001 | G45: 2 | H45: 0 | I45: 0.001 | J45: 2.6495255e+16
C46: B1 | E46: 0.047 | F46: -0.001
B47: SPL1 | C47: C2 | E47: 1.555 | F47: 1.508 | G47: 2 | H47: 1.493 | I47: 0.022 | J47: 1.459
...

Sheet ECOA_10_10_24_Optimization
A1: Standard | B1: Absorbance | C1: Mean | D1: CV | F1: CorrAbs | H1: Concentation | I1: Log (Conc)
A2: Blank | B2: =ECOA_10_10_24_RawData!E45 -> 0.048 | C2: =AVERAGE(B2,B3) -> 0.0475 | D2: =100*(STDEV(B2,B3)/C2) -> 1.4886459 | F2: =C2-$C$2 -> 0 | H2: 0
A3: Blank | B3: =ECOA_10_10_24_RawData!E46 -> 0.047 | K3: Data for Plot
A4: STD_0 | B4: =ECOA_10_10_24_RawData!E67 -> 0.106 | C4: =AVERAGE(B4,B5) -> 0.085 | D4: =100*(STDEV(B4,B5)/C4) -> 34.939394 | F4: =C4-$C$2 -> 0.0375 | H4: 0 | I4: 0 | K4: 0 | L4: =G2 -> 0
A5: STD_0 | B5: =ECOA_10_10_24_RawData!E68 -> 0.064 | K5: 300 | L5: =F4 -> 0.0375 | N5: NOTES | O5: Issue with Standard Curve
A6: STD_1 | B6: =ECOA_10_10_24_RawData!E69 -> 0.064 | C6: =AVERAGE(B6,B7) -> 0.0625 | D6: =100*(STDEV(B6,B7)/C6) -> 3.3941125 | F6: =C6-$C$2 -> 0.015 | H6: 300 | I6: =LOG10(H6) -> 2.4771213 | K6: 600 | L6: =F6 -> 0.015
A7: STD_1 | B7: =ECOA_10_10_24_RawData!E70 -> 0.061 | K7: 1000 | L7: =F8 -> 0.0145
A8: STD_2 | B8: =ECOA_10_10_24_RawData!E71 -> 0.066 | C8: =AVERAGE(B8,B9) -> 0.062 | D8: =100*(STDEV(B8,B9)/C8) -> 9.1239585 | F8: =C8-$C$2 -> 0.0145 | H8: 600 | I8: =LOG10(H8) -> 2.7781513
A9: STD_2 | B9: =ECOA_10_10_24_RawData!E72 -> 0.058 | K9: Slope | L9: 5e-06
A10: STD_3 | B10: =ECOA_10_10_24_RawData!E73 -> 0.068 | C10: =AVERAGE(B10,B11) -> 0.1945 | D10: =100*(STDEV(B10,B11)/C10) -> 91.978414 | F10: =C10-$C$2 -> 0.147 | H10: 1000 | I10: =LOG10(H10) -> 3 | K10: Intercept | L10: 0.0142
A11: STD_3 | B11: =ECOA_10_10_24_RawData!E74 -> 0.321
A13: Sample Name | B13: Absorbance | C13: Mean | D13: CV | E13: CorrAbs | F13: Final Concentration | G13: Corrected Concentration
A14: GH_Pool | B14: =ECOA_10_10_24_RawData!E47 -> 1.555 | C14: =AVERAGE(B14,B15) -> 1.5395 | D14: =100*(STDEV(B14,B15)/C14) -> 1.4238591 | E14: =C14-$C$2 -> 1.492 | F14: =(E14-$L$10)/$L$9 -> 295560 | G14: =F14 -> 295560
B15: =ECOA_10_10_24_RawData!E48 -> 1.524
A16: GH_Pool_1:2 | B16: =ECOA_10_10_24_RawData!E49 -> 2.141 | C16: =AVERAGE(B16,B17) -> 1.723 | D16: =100*(STDEV(B16,B17)/C16) -> 34.308837 | E16: =C16-$C$2 -> 1.6755 | F16: =(E16-$L$10)/$L$9 -> 332260 | G16: =F16/2 -> 166130
B17: =ECOA_10_10_24_RawData!E50 -> 1.305
A18: GH_Pool_1:4 | B18: =ECOA_10_10_24_RawData!E51 -> 1.02 | C18: =AVERAGE(B18,B19) -> 1.023 | D18: =100*(STDEV(B18,B19)/C18) -> 0.41472538 | E18: =C18-$C$2 -> 0.9755 | F18: =(E18-$L$10)/$L$9 -> 192260 | G18: =F18/4 -> 48065
B19: =ECOA_10_10_24_RawData!E52 -> 1.026 | H19: Sample Color Scheme: | J19: Overwinter | K19: Greenhouse
A20: GH_Pool_1:8 | B20: =ECOA_10_10_24_RawData!E53 -> 0.709 | C20: =AVERAGE(B20,B21) -> 0.7205 | D20: =100*(STDEV(B20,B21)/C20) -> 2.2572458 | E20: =C20-$C$2 -> 0.673 | F20: =(E20-$L$10)/$L$9 -> 131760 | G20: =F20/8 -> 16470 | H20: Red highlight means CV > 10
B21: =ECOA_10_10_24_RawData!E54 -> 0.732
A22: OW_Pool | B22: =ECOA_10_10_24_RawData!E55 -> 1.584 | C22: =AVERAGE(B22,B23) -> 1.5695 | D22: =100*(STDEV(B22,B23)/C22) -> 1.3065369 | E22: =C22-$C$2 -> 1.522 | F22: =(E22-$L$10)/$L$9 -> 301560 | G22: =F22 -> 301560 | I22: dilution | J22: Overwinter | K22: Greenhouse
B23: =ECOA_10_10_24_RawData!E56 -> 1.555 | I23: 1 | J23: 1.5695 | K23: 1.5395
A24: OW_Pool_1:2 | B24: =ECOA_10_10_24_RawData!E57 -> 1.298 | C24: =AVERAGE(B24,B25) -> 1.299 | D24: =100*(STDEV(B24,B25)/C24) -> 0.1088694 | E24: =C24-$C$2 -> 1.2515 | F24: =(E24-$L$10)/$L$9 -> 247460 | G24: =F24/2 -> 123730 | I24: 0.5 | J24: 1.299 | K24: 1.723
B25: =ECOA_10_10_24_RawData!E58 -> 1.3 | I25: 0.25 | J25: 0.8725 | K25: 1.023 | N25: 3
A26: OW_Pool_1:4 | B26: =ECOA_10_10_24_RawData!E59 -> 0.879 | C26: =AVERAGE(B26,B27) -> 0.8725 | D26: =100*(STDEV(B26,B27)/C26) -> 1.0535688 | E26: =C26-$C$2 -> 0.825 | F26: =(E26-$L$10)/$L$9 -> 162160 | G26: =F26/4 -> 40540 | I26: 0.125 | J26: 0.5135 | K26: 0.7205 | N26: 1
B27: =ECOA_10_10_24_RawData!E60 -> 0.866
A28: OW_Pool_1:8 | B28: =ECOA_10_10_24_RawData!E61 -> 0.512 | C28: =AVERAGE(B28,B29) -> 0.5135 | D28: =100*(STDEV(B28,B29)/C28) -> 0.4131101 | E28: =C28-$C$2 -> 0.466 | F28: =(E28-$L$10)/$L$9 -> 90360 | G28: =F28/8 -> 11295
B29: =ECOA_10_10_24_RawData!E62 -> 0.515
A30: 3.2 | B30: =ECOA_10_10_24_RawData!E63 -> 1.621 | C30: =AVERAGE(B30,B31) -> 1.6015 | D30: =100*(STDEV(B30,B31)/C30) -> 1.7219584 | E30: =C30-$C$2 -> 1.554 | F30: =(E30-$L$10)/$L$9 -> 307960 | G30: =F30 -> 307960
B31: =ECOA_10_10_24_RawData!E64 -> 1.582
A32: 5.2 | B32: =ECOA_10_10_24_RawData!E65 -> 1.482 | C32: =AVERAGE(B32,B33) -> 1.1955 | D32: =100*(STDEV(B32,B33)/C32) -> 33.891442 | E32: =C32-$C$2 -> 1.148 | F32: =(E32-$L$10)/$L$9 -> 226760 | G32: =F32 -> 226760
B33: =ECOA_10_10_24_RawData!E66 -> 0.909
A35: NOTES: | B35: Repeat assay and remake STD curve.
