Workbook
Name MethodPointer: 166869040
Name MethodPointer: 168934704
Name MethodPointer: 166869040
Name MethodPointer: 172016408
Name MethodPointer: 166869040
Name MethodPointer: 171201064
Name MethodPointer: 166869040
Name MethodPointer: 168882816
Name MethodPointer: 166869040
Name MethodPointer: 159441416
Name MethodPointer: 166869040
Name MethodPointer: 166869040
Name MethodPointer: 11486024
Name MethodPointer: 166869040
Name MethodPointer: 42203784
Name MethodPointer: 159003584

Sheet Plate5_Analysis_11_29
A1: Standard | B1: Absorbance | C1: Mean | D1: CV | F1: CorrAbs | H1: Concentation | K1: Data for Plot
A2: Blank | B2: =Plate5_RawData_11_29!E49 -> 0.044 | C2: =AVERAGE(B2,B3) -> 0.0435 | D2: =100*(STDEV(B2,B3)/C2) -> 1.6255328 | F2: =C2-$C$2 -> 0 | H2: 0 | K2: 0 | L2: =F4 -> -0.0015
A3: Blank | B3: =Plate5_RawData_11_29!E50 -> 0.043 | K3: 12.5 | L3: =F6 -> 0.0135
A4: S0 | B4: =Plate5_RawData_11_29!E101 -> 0.045 | C4: 0.042 | D4: =100*(STDEV(B4,B5)/C4) -> 8.4179379 | F4: =C4-$C$2 -> -0.0015 | H4: 0 | K4: 50 | L4: =F8 -> 0.0585
A5: S0 | B5: =Plate5_RawData_11_29!E102 -> 0.05 | K5: 100 | L5: =F10 -> 0.102
A6: S1 | B6: =Plate5_RawData_11_29!E103 -> 0.057 | C6: =AVERAGE(B6,B7) -> 0.057 | D6: =100*(STDEV(B6,B7)/C6) -> 0 | F6: =C6-$C$2 -> 0.0135 | H6: 12.5 | K6: 150 | L6: =F12 -> 0.154
A7: S1 | B7: =Plate5_RawData_11_29!E104 -> 0.057 | K7: 200 | L7: =F14 -> 0.189
A8: S3 | B8: =Plate5_RawData_11_29!E105 -> 0.102 | C8: =AVERAGE(B8,B9) -> 0.102 | D8: =100*(STDEV(B8,B9)/C8) -> 0 | F8: =C8-$C$2 -> 0.0585 | H8: 50
A9: S3 | B9: =Plate5_RawData_11_29!E106 -> 0.102 | K9: Slope | L9: 0.001
A10: S5 | B10: =Plate5_RawData_11_29!E107 -> 0.141 | C10: =AVERAGE(B10,B11) -> 0.1455 | D10: =100*(STDEV(B10,B11)/C10) -> 4.3738564 | F10: =C10-$C$2 -> 0.102 | H10: 100 | K10: Intercept | L10: 0.0038
A11: S5 | B11: =Plate5_RawData_11_29!E108 -> 0.15
A12: S7 | B12: =Plate5_RawData_11_29!E109 -> 0.19 | C12: =AVERAGE(B12,B13) -> 0.1975 | D12: =100*(STDEV(B12,B13)/C12) -> 5.3704312 | F12: =C12-$C$2 -> 0.154 | H12: 150
A13: S7 | B13: =Plate5_RawData_11_29!E110 -> 0.205
A14: S9 | B14: =Plate5_RawData_11_29!E111 -> 0.228 | C14: =AVERAGE(B14,B15) -> 0.2325 | D14: =100*(STDEV(B14,B15)/C14) -> 2.7371875 | F14: =C14-$C$2 -> 0.189 | H14: 200
A15: S9 | B15: =Plate5_RawData_11_29!E112 -> 0.237
A20: Sample Name | B20: Absorbance | C20: Mean | D20: CV | E20: CorrAbs | F20: Final Concentration | H20: Color Scheme: | J20: Overwinter | K20: Greenhouse
A21: 2.2 (A) | B21: =Plate5_RawData_11_29!E67 -> 0.122 | C21: =AVERAGE(B21,B22) -> 0.124 | D21: =100*(STDEV(B21,B22)/C21) -> 2.2809896 | E21: =C21-$C$2 -> 0.0805 | F21: =(E21-$L$10)/$L$9 -> 76.7
B22: =Plate5_RawData_11_29!E68 -> 0.126
A23: 10.1 (A) | B23: =Plate5_RawData_11_29!E69 -> 0.126 | C23: =AVERAGE(B23,B24) -> 0.1265 | D23: =100*(STDEV(B23,B24)/C23) -> 0.55897769 | E23: =C23-$C$2 -> 0.083 | F23: =(E23-$L$10)/$L$9 -> 79.2
B24: =Plate5_RawData_11_29!E70 -> 0.127
A25: 15.2 (A) | B25: =Plate5_RawData_11_29!E71 -> 0.119 | C25: =AVERAGE(B25,B26) -> 0.124 | D25: =100*(STDEV(B25,B26)/C25) -> 5.702474 | E25: =C25-$C$2 -> 0.0805 | F25: =(E25-$L$10)/$L$9 -> 76.7
B26: =Plate5_RawData_11_29!E72 -> 0.129
A27: 10.1 (D) | B27: =Plate5_RawData_11_29!E73 -> 0.052 | C27: =AVERAGE(B27,B28) -> 0.052 | D27: =100*(STDEV(B27,B28)/C27) -> 0 | E27: =C27-$C$2 -> 0.0085 | F27: =(E27-$L$10)/$L$9 -> 4.7 | J27: Timepoint | K27: Label
B28: =Plate5_RawData_11_29!E74 -> 0.052 | J28: Baseline | K28: A
A29: 12.5 (A) | B29: =Plate5_RawData_11_29!E75 -> 0.125 | C29: =AVERAGE(B29,B30) -> 0.1255 | D29: =100*(STDEV(B29,B30)/C29) -> 0.5634317 | E29: =C29-$C$2 -> 0.082 | F29: =(E29-$L$10)/$L$9 -> 78.2 | J29: Cold Dormancy | K29: B
B30: =Plate5_RawData_11_29!E76 -> 0.126 | J30: 3 weeks | K30: C
A31: 10.1 (C) | B31: =Plate5_RawData_11_29!E77 -> 0.106 | C31: =AVERAGE(B31,B32) -> 0.1065 | D31: =100*(STDEV(B31,B32)/C31) -> 0.66395003 | E31: =C31-$C$2 -> 0.063 | F31: =(E31-$L$10)/$L$9 -> 59.2 | J31: 3 months | K31: D
B32: =Plate5_RawData_11_29!E78 -> 0.107
A33: 9.3 (D) | B33: =Plate5_RawData_11_29!E79 -> 0.153 | C33: =AVERAGE(B33,B34) -> 0.15 | D33: =100*(STDEV(B33,B34)/C33) -> 2.8284271 | E33: =C33-$C$2 -> 0.1065 | F33: =(E33-$L$10)/$L$9 -> 102.7
B34: =Plate5_RawData_11_29!E80 -> 0.147
A35: 15.2 (C) | B35: =Plate5_RawData_11_29!E81 -> 0.082 | C35: =AVERAGE(B35,B36) -> 0.0815 | D35: =100*(STDEV(B35,B36)/C35) -> 0.86761568 | E35: =C35-$C$2 -> 0.038 | F35: =(E35-$L$10)/$L$9 -> 34.2
B36: =Plate5_RawData_11_29!E82 -> 0.081
A37: 2.2 (A) | B37: =Plate5_RawData_11_29!E83 -> 0.115 | C37: =AVERAGE(B37,B38) -> 0.116 | D37: =100*(STDEV(B37,B38)/C37) -> 1.2191496 | E37: =C37-$C$2 -> 0.0725 | F37: =(E37-$L$10)/$L$9 -> 68.7
B38: =Plate5_RawData_11_29!E84 -> 0.117
A39: 12.5 (C) | B39: =Plate5_RawData_11_29!E85 -> 0.064 | C39: =AVERAGE(B39,B40) -> 0.0645 | D39: =100*(STDEV(B39,B40)/C39) -> 1.0962896 | E39: =C39-$C$2 -> 0.021 | F39: =(E39-$L$10)/$L$9 -> 17.2
B40: =Plate5_RawData_11_29!E86 -> 0.065
A41: 15.1 (D) | B41: =Plate5_RawData_11_29!E87 -> 0.134 | C41: =AVERAGE(B41,B42) -> 0.135 | D41: =100*(STDEV(B41,B42)/C41) -> 1.0475656 | E41: =C41-$C$2 -> 0.0915 | F41: =(E41-$L$10)/$L$9 -> 87.7
B42: =Plate5_RawData_11_29!E88 -> 0.136
A43: 15.1 (A) | B43: =Plate5_RawData_11_29!E89 -> 0.087 | C43: =AVERAGE(B43,B44) -> 0.084 | D43: =100*(STDEV(B43,B44)/C43) -> 5.0507627 | E43: =C43-$C$2 -> 0.0405 | F43: =(E43-$L$10)/$L$9 -> 36.7
B44: =Plate5_RawData_11_29!E90 -> 0.081
...

Sheet Plate5_RawData_11_29
A2: Software Version | B2: 2.09.1
A4: Experiment File Path: | B4: E:\GT_Metabolomics\TRIG_11_29_24_Plate5.xpt
A5: Protocol File Path: | B5: C:\Users\Public\Documents\Protocols\Schwartz_TRIG.prt
A6: Plate Number | B6: Plate 1
A7: Date | B7: 45625
A8: Time | B8: 0.92414352
A9: Reader Type: | B9: Cytation3
A10: Reader Serial Number: | B10: 13081218
A11: Reading Type | B11: Reader
A13: Procedure Details
A14: Plate Type | B14: 96 WELL PLATE
A15: Eject plate on completion
A16: Read | B16: Absorbance Endpoint
B17: Full Plate
B18: Wavelengths: 500
B19: Read Speed: Normal, Delay: 100 msec, Measurements/Data Point: 8
A21: Layout
C23: 1 | D23: 2 | E23: 3 | F23: 4 | G23: 5 | H23: 6 | I23: 7 | J23: 8 | K23: 9 | L23: 10 | M23: 11 | N23: 12
B24: A | C24: BLK | D24: STD4 | E24: SPL2 | F24: SPL6 | G24: BLK | H24: SPL14 | I24: BLK | J24: SPL22 | O24: Well ID
D25: 100 | O25: Conc/Dil
B26: B | C26: BLK | D26: STD4 | E26: SPL2 | F26: SPL6 | G26: BLK | H26: SPL14 | I26: BLK | J26: SPL22 | O26: Well ID
D27: 100 | O27: Conc/Dil
B28: C | C28: STD1 | D28: STD5 | E28: SPL3 | F28: SPL7 | G28: SPL11 | H28: BLK | I28: SPL19 | J28: SPL23 | O28: Well ID
C29: 0 | D29: 150 | O29: Conc/Dil
B30: D | C30: STD1 | D30: STD5 | E30: SPL3 | F30: SPL7 | G30: SPL11 | H30: BLK | I30: SPL19 | J30: SPL23 | O30: Well ID
C31: 0 | D31: 150 | O31: Conc/Dil
B32: E | C32: STD2 | D32: STD6 | E32: BLK | F32: SPL8 | G32: SPL12 | H32: SPL16 | I32: BLK | J32: SPL24 | O32: Well ID
C33: 12.5 | D33: 200 | O33: Conc/Dil
B34: F | C34: STD2 | D34: STD6 | E34: BLK | F34: SPL8 | G34: SPL12 | H34: SPL16 | I34: BLK | J34: SPL24 | O34: Well ID
C35: 12.5 | D35: 200 | O35: Conc/Dil
B36: G | C36: STD3 | D36: SPL1 | E36: BLK | F36: SPL9 | G36: BLK | H36: BLK | I36: SPL21 | J36: SPL25 | O36: Well ID
C37: 50 | O37: Conc/Dil
B38: H | C38: STD3 | D38: SPL1 | E38: BLK | F38: SPL9 | G38: BLK | H38: BLK | I38: SPL21 | J38: SPL25 | O38: Well ID
C39: 50 | O39: Conc/Dil
A41: 500
A42: Actual Temperature: | B42: 26.5
A43: Actual Temperature: | B43: 26.5
A44: Actual Temperature: | B44: 26.5
A45: Actual Temperature: | B45: 26.5
A46: Actual Temperature: | B46: 26.5
...

Sheet Plate4_Analysis_11_29
A1: Standard | B1: Absorbance | C1: Mean | D1: CV | F1: CorrAbs | H1: Concentation | K1: Data for Plot
A2: Blank | B2: =Plate4_RawData_11_29!E190 -> 0.042 | C2: =AVERAGE(B2,B3) -> 0.0435 | D2: =100*(STDEV(B2,B3)/C2) -> 4.8765985 | F2: =C2-$C$2 -> 0 | H2: 0 | K2: 0 | L2: =F4 -> -0.0015
A3: Blank | B3: =Plate4_RawData_11_29!E191 -> 0.045 | K3: 12.5 | L3: =F6 -> 0.0135
A4: S0 | B4: =Plate4_RawData_11_29!E274 -> 0.044 | C4: 0.042 | D4: =100*(STDEV(B4,B5)/C4) -> 1.6835876 | F4: =C4-$C$2 -> -0.0015 | H4: 0 | K4: 50 | L4: =F8 -> 0.051
A5: S0 | B5: =Plate4_RawData_11_29!E275 -> 0.043 | K5: 100 | L5: =F10 -> 0.108
A6: S1 | B6: =Plate4_RawData_11_29!E276 -> 0.055 | C6: =AVERAGE(B6,B7) -> 0.057 | D6: =100*(STDEV(B6,B7)/C6) -> 4.9621529 | F6: =C6-$C$2 -> 0.0135 | H6: 12.5 | K6: 150 | L6: =F12 -> 0.1405
A7: S1 | B7: =Plate4_RawData_11_29!E277 -> 0.059 | K7: 200 | L7: =F14 -> 0.191
A8: S3 | B8: =Plate4_RawData_11_29!E278 -> 0.093 | C8: =AVERAGE(B8,B9) -> 0.0945 | D8: =100*(STDEV(B8,B9)/C8) -> 2.2447834 | F8: =C8-$C$2 -> 0.051 | H8: 50
A9: S3 | B9: =Plate4_RawData_11_29!E279 -> 0.096 | K9: Slope | L9: 0.001
A10: S5 | B10: =Plate4_RawData_11_29!E280 -> 0.155 | C10: =AVERAGE(B10,B11) -> 0.1515 | D10: =100*(STDEV(B10,B11)/C10) -> 3.26716 | F10: =C10-$C$2 -> 0.108 | H10: 100 | K10: Intercept | L10: 0.0024
A11: S5 | B11: =Plate4_RawData_11_29!E281 -> 0.148
A12: S7 | B12: =Plate4_RawData_11_29!E282 -> 0.168 | C12: =AVERAGE(B12,B13) -> 0.184 | D12: =100*(STDEV(B12,B13)/C12) -> 12.297509 | F12: =C12-$C$2 -> 0.1405 | H12: 150
A13: S7 | B13: =Plate4_RawData_11_29!E283 -> 0.2
A14: S9 | B14: =Plate4_RawData_11_29!E284 -> 0.227 | C14: =AVERAGE(B14,B15) -> 0.2345 | D14: =100*(STDEV(B14,B15)/C14) -> 4.5230711 | F14: =C14-$C$2 -> 0.191 | H14: 200
A15: S9 | B15: =Plate4_RawData_11_29!E285 -> 0.242
A20: Sample Name | B20: Absorbance | C20: Mean | D20: CV | E20: CorrAbs | F20: Final Concentration | H20: Color Scheme: | J20: Overwinter | K20: Greenhouse
A21: GH_Pool | B21: =Plate4_RawData_11_29!E293 -> 0.161 | C21: =AVERAGE(B21,B22) -> 0.1645 | D21: =100*(STDEV(B21,B22)/C21) -> 3.008965 | E21: =C21-$C$2 -> 0.121 | F21: =(E21-$L$10)/$L$9 -> 118.6
B22: =Plate4_RawData_11_29!E294 -> 0.168
A23: 5.5 (A) | B23: =Plate4_RawData_11_29!E295 -> 0.146 | C23: =AVERAGE(B23,B24) -> 0.1525 | D23: =100*(STDEV(B23,B24)/C23) -> 6.0277955 | E23: =C23-$C$2 -> 0.109 | F23: =(E23-$L$10)/$L$9 -> 106.6
B24: =Plate4_RawData_11_29!E296 -> 0.159
A25: 3.2 (A) | B25: =Plate4_RawData_11_29!E297 -> 0.109 | C25: =AVERAGE(B25,B26) -> 0.097 | D25: =100*(STDEV(B25,B26)/C25) -> 17.495426 | E25: =C25-$C$2 -> 0.0535 | F25: =(E25-$L$10)/$L$9 -> 51.1
B26: =Plate4_RawData_11_29!E298 -> 0.085
A27: 2.2 (A) | B27: =Plate4_RawData_11_29!E299 -> 0.122 | C27: =AVERAGE(B27,B28) -> 0.1205 | D27: =100*(STDEV(B27,B28)/C27) -> 1.7604318 | E27: =C27-$C$2 -> 0.077 | F27: =(E27-$L$10)/$L$9 -> 74.6 | J27: Timepoint | K27: Label
B28: =Plate4_RawData_11_29!E300 -> 0.119 | J28: Baseline | K28: A
A29: 12.6 (A) | B29: =Plate4_RawData_11_29!E301 -> 0.09 | C29: =AVERAGE(B29,B30) -> 0.093 | D29: =100*(STDEV(B29,B30)/C29) -> 4.5619792 | E29: =C29-$C$2 -> 0.0495 | F29: =(E29-$L$10)/$L$9 -> 47.1 | J29: Cold Dormancy | K29: B
B30: =Plate4_RawData_11_29!E302 -> 0.096 | J30: 3 weeks | K30: C
A31: 5.5 (D) | B31: =Plate4_RawData_11_29!E303 -> 0.198 | C31: =AVERAGE(B31,B32) -> 0.197 | D31: =100*(STDEV(B31,B32)/C31) -> 0.7178749 | E31: =C31-$C$2 -> 0.1535 | F31: =(E31-$L$10)/$L$9 -> 151.1 | J31: 3 months | K31: D
B32: =Plate4_RawData_11_29!E304 -> 0.196
A33: 6.5 (A) | B33: =Plate4_RawData_11_29!E305 -> 0.084 | C33: =AVERAGE(B33,B34) -> 0.089 | D33: =100*(STDEV(B33,B34)/C33) -> 7.94502 | E33: =C33-$C$2 -> 0.0455 | F33: =(E33-$L$10)/$L$9 -> 43.1
B34: =Plate4_RawData_11_29!E306 -> 0.094
A35: 2.2 (A) | B35: =Plate4_RawData_11_29!E307 -> 0.117 | C35: =AVERAGE(B35,B36) -> 0.1195 | D35: =100*(STDEV(B35,B36)/C35) -> 2.9586058 | E35: =C35-$C$2 -> 0.076 | F35: =(E35-$L$10)/$L$9 -> 73.6
B36: =Plate4_RawData_11_29!E308 -> 0.122
A37: 13.1 (D) | B37: =Plate4_RawData_11_29!E309 -> 0.129 | C37: =AVERAGE(B37,B38) -> 0.1355 | D37: =100*(STDEV(B37,B38)/C37) -> 6.7840503 | E37: =C37-$C$2 -> 0.092 | F37: =(E37-$L$10)/$L$9 -> 89.6
B38: =Plate4_RawData_11_29!E310 -> 0.142
A39: 9.5 (A) | B39: =Plate4_RawData_11_29!E311 -> 0.115 | C39: =AVERAGE(B39,B40) -> 0.112 | D39: =100*(STDEV(B39,B40)/C39) -> 3.788072 | E39: =C39-$C$2 -> 0.0685 | F39: =(E39-$L$10)/$L$9 -> 66.1
B40: =Plate4_RawData_11_29!E312 -> 0.109
A41: 3.2 (C) | B41: =Plate4_RawData_11_29!E313 -> 0.1 | C41: =AVERAGE(B41,B42) -> 0.1025 | D41: =100*(STDEV(B41,B42)/C41) -> 3.4493014 | E41: =C41-$C$2 -> 0.059 | F41: =(E41-$L$10)/$L$9 -> 56.6
B42: =Plate4_RawData_11_29!E314 -> 0.105
A43: 12.6 (D) | B43: =Plate4_RawData_11_29!E315 -> 0.091 | C43: =AVERAGE(B43,B44) -> 0.0935 | D43: =100*(STDEV(B43,B44)/C43) -> 3.7813197 | E43: =C43-$C$2 -> 0.05 | F43: =(E43-$L$10)/$L$9 -> 47.6
B44: =Plate4_RawData_11_29!E316 -> 0.096
...

Sheet Plate4_RawData_11_29
A2: Software Version | B2: 2.09.1
A4: Experiment File Path: | B4: E:\GT_Metabolomics\TRIG_11_29_24_Plate4.xpt
A5: Protocol File Path: | B5: C:\Users\Public\Documents\Protocols\Schwartz_TRIG.prt
A6: Plate Number | B6: Plate 1
A7: Date | B7: 45625
A8: Time | B8: 0.78790509
A9: Reader Type: | B9: Cytation3
A10: Reader Serial Number: | B10: Unknown
A11: Reading Type | B11: Reader
A13: Procedure Details
A14: Plate Type | B14: 96 WELL PLATE
A15: Eject plate on completion
A16: Read | B16: Absorbance Endpoint
B17: Full Plate
B18: Wavelengths: 500
B19: Read Speed: Normal, Delay: 100 msec, Measurements/Data Point: 8
A21: Layout
C23: 1 | D23: 2 | E23: 3 | F23: 4 | G23: 5 | H23: 6 | I23: 7 | J23: 8 | K23: 9 | L23: 10 | M23: 11 | N23: 12
B24: A | C24: BLK | D24: STD4 | E24: SPL2 | F24: SPL6 | G24: SPL10 | H24: SPL14 | I24: SPL18 | J24: SPL22 | K24: SPL26 | L24: SPL30 | M24: SPL34 | N24: SPL38 | O24: Well ID
D25: 100 | O25: Conc/Dil
B26: B | C26: BLK | D26: STD4 | E26: SPL2 | F26: SPL6 | G26: SPL10 | H26: SPL14 | I26: SPL18 | J26: SPL22 | K26: SPL26 | L26: SPL30 | M26: SPL34 | N26: SPL38 | O26: Well ID
D27: 100 | O27: Conc/Dil
B28: C | C28: STD1 | D28: STD5 | E28: SPL3 | F28: SPL7 | G28: SPL11 | H28: SPL15 | I28: SPL19 | J28: SPL23 | K28: SPL27 | L28: SPL31 | M28: SPL35 | N28: SPL39 | O28: Well ID
C29: 0 | D29: 150 | O29: Conc/Dil
B30: D | C30: STD1 | D30: STD5 | E30: SPL3 | F30: SPL7 | G30: SPL11 | H30: SPL15 | I30: SPL19 | J30: SPL23 | K30: SPL27 | L30: SPL31 | M30: SPL35 | N30: SPL39 | O30: Well ID
C31: 0 | D31: 150 | O31: Conc/Dil
B32: E | C32: STD2 | D32: STD6 | E32: SPL4 | F32: SPL8 | G32: SPL12 | H32: SPL16 | I32: SPL20 | J32: SPL24 | K32: SPL28 | L32: SPL32 | M32: SPL36 | N32: SPL40 | O32: Well ID
C33: 12.5 | D33: 200 | O33: Conc/Dil
B34: F | C34: STD2 | D34: STD6 | E34: SPL4 | F34: SPL8 | G34: SPL12 | H34: SPL16 | I34: SPL20 | J34: SPL24 | K34: SPL28 | L34: SPL32 | M34: SPL36 | N34: SPL40 | O34: Well ID
C35: 12.5 | D35: 200 | O35: Conc/Dil
B36: G | C36: STD3 | D36: SPL1 | E36: SPL5 | F36: SPL9 | G36: SPL13 | H36: SPL17 | I36: SPL21 | J36: SPL25 | K36: SPL29 | L36: SPL33 | M36: SPL37 | N36: SPL41 | O36: Well ID
C37: 50 | O37: Conc/Dil
B38: H | C38: STD3 | D38: SPL1 | E38: SPL5 | F38: SPL9 | G38: SPL13 | H38: SPL17 | I38: SPL21 | J38: SPL25 | K38: SPL29 | L38: SPL33 | M38: SPL37 | N38: SPL41 | O38: Well ID
C39: 50 | O39: Conc/Dil
A41: 500
A42: Actual Temperature: | B42: 26.2
A43: Actual Temperature: | B43: 26.2
A44: Actual Temperature: | B44: 26.2
A45: Actual Temperature: | B45: 26.2
A46: Actual Temperature: | B46: 26.2
...

Sheet Plate3_Analysis_11_29
A1: Standard | B1: Absorbance | C1: Mean | D1: CV | F1: CorrAbs | H1: Concentation | K1: Data for Plot
A2: Blank | B2: =Plate3_RawData_11_29!E190 -> 0.042 | C2: =AVERAGE(B2,B3) -> 0.042 | D2: =100*(STDEV(B2,B3)/C2) -> 0 | F2: =C2-$C$2 -> 0 | H2: 0 | K2: 0 | L2: =F4 -> 0
A3: Blank | B3: =Plate3_RawData_11_29!E191 -> 0.042 | K3: 12.5 | L3: =F6 -> 0.0155
A4: S0 | B4: =Plate3_RawData_11_29!E274 -> 0.042 | C4: 0.042 | D4: =100*(STDEV(B4,B5)/C4) -> 21.886638 | F4: =C4-$C$2 -> 0 | H4: 0 | K4: 50 | L4: =F8 -> 0.053
A5: S0 | B5: =Plate3_RawData_11_29!E275 -> 0.055 | C5: Data point thrown out as its close to S1 and not similar to previous runs | K5: 100 | L5: =F10 -> 0.0975
A6: S1 | B6: =Plate3_RawData_11_29!E276 -> 0.058 | C6: =AVERAGE(B6,B7) -> 0.0575 | D6: =100*(STDEV(B6,B7)/C6) -> 1.2297509 | F6: =C6-$C$2 -> 0.0155 | H6: 12.5 | K6: 150 | L6: =F12 -> 0.155
A7: S1 | B7: =Plate3_RawData_11_29!E277 -> 0.057 | K7: 200 | L7: =F14 -> 0.195
A8: S3 | B8: =Plate3_RawData_11_29!E278 -> 0.093 | C8: =AVERAGE(B8,B9) -> 0.095 | D8: =100*(STDEV(B8,B9)/C8) -> 2.9772917 | F8: =C8-$C$2 -> 0.053 | H8: 50
A9: S3 | B9: =Plate3_RawData_11_29!E279 -> 0.097 | K9: Slope | L9: 0.001
A10: S5 | B10: =Plate3_RawData_11_29!E280 -> 0.133 | C10: =AVERAGE(B10,B11) -> 0.1395 | D10: =100*(STDEV(B10,B11)/C10) -> 6.5895256 | F10: =C10-$C$2 -> 0.0975 | H10: 100 | K10: Intercept | L10: 0.0022
A11: S5 | B11: =Plate3_RawData_11_29!E281 -> 0.146
A12: S7 | B12: =Plate3_RawData_11_29!E282 -> 0.198 | C12: =AVERAGE(B12,B13) -> 0.197 | D12: =100*(STDEV(B12,B13)/C12) -> 0.7178749 | F12: =C12-$C$2 -> 0.155 | H12: 150
A13: S7 | B13: =Plate3_RawData_11_29!E283 -> 0.196
A14: S9 | B14: =Plate3_RawData_11_29!E284 -> 0.236 | C14: =AVERAGE(B14,B15) -> 0.237 | D14: =100*(STDEV(B14,B15)/C14) -> 0.59671458 | F14: =C14-$C$2 -> 0.195 | H14: 200
A15: S9 | B15: =Plate3_RawData_11_29!E285 -> 0.238
A20: Sample Name | B20: Absorbance | C20: Mean | D20: CV | E20: CorrAbs | F20: Final Concentration | H20: Color Scheme: | J20: Overwinter | K20: Greenhouse
A21: GH_Pool | B21: =Plate3_RawData_11_29!E293 -> 0.143 | C21: =AVERAGE(B21,B22) -> 0.155 | D21: =100*(STDEV(B21,B22)/C21) -> 10.94875 | E21: =C21-$C$2 -> 0.113 | F21: =(E21-$L$10)/$L$9 -> 110.8
B22: =Plate3_RawData_11_29!E294 -> 0.167
A23: 2.2 (A) | B23: =Plate3_RawData_11_29!E295 -> 0.116 | C23: =AVERAGE(B23,B24) -> 0.118 | D23: =100*(STDEV(B23,B24)/C23) -> 2.3969721 | E23: =C23-$C$2 -> 0.076 | F23: =(E23-$L$10)/$L$9 -> 73.8 | J23: 94.2
B24: =Plate3_RawData_11_29!E296 -> 0.12 | J24: 40.7
A25: 5.4 (A) | B25: =Plate3_RawData_11_29!E297 -> 0.065 | C25: =AVERAGE(B25,B26) -> 0.0695 | D25: =100*(STDEV(B25,B26)/C25) -> 9.1567785 | E25: =C25-$C$2 -> 0.0275 | F25: =(E25-$L$10)/$L$9 -> 25.3 | J25: 97.2
B26: =Plate3_RawData_11_29!E298 -> 0.074 | J26: 55.7
A27: 7.1 (D) | B27: =Plate3_RawData_11_29!E299 -> 0.094 | C27: =AVERAGE(B27,B28) -> 0.0955 | D27: =100*(STDEV(B27,B28)/C27) -> 2.2212778 | E27: =C27-$C$2 -> 0.0535 | F27: =(E27-$L$10)/$L$9 -> 51.3 | J27: 66.2 | K27: Label
B28: =Plate3_RawData_11_29!E300 -> 0.097 | J28: 107.7 | K28: A
A29: 5.3 (A) | B29: =Plate3_RawData_11_29!E301 -> 0.078 | C29: =AVERAGE(B29,B30) -> 0.078 | D29: =100*(STDEV(B29,B30)/C29) -> 0 | E29: =C29-$C$2 -> 0.036 | F29: =(E29-$L$10)/$L$9 -> 33.8 | J29: 63.2 | K29: B
B30: =Plate3_RawData_11_29!E302 -> 0.078 | J30: 179.2 | K30: C
A31: 2.2 (A) | B31: =Plate3_RawData_11_29!E303 -> 0.115 | C31: =AVERAGE(B31,B32) -> 0.1145 | D31: =100*(STDEV(B31,B32)/C31) -> 0.61756051 | E31: =C31-$C$2 -> 0.0725 | F31: =(E31-$L$10)/$L$9 -> 70.3 | J31: 38.7 | K31: D
B32: =Plate3_RawData_11_29!E304 -> 0.114 | J32: 119.2
A33: 6.2 (A) | B33: =Plate3_RawData_11_29!E305 -> 0.073 | C33: =AVERAGE(B33,B34) -> 0.0775 | D33: =100*(STDEV(B33,B34)/C33) -> 8.2115626 | E33: =C33-$C$2 -> 0.0355 | F33: =(E33-$L$10)/$L$9 -> 33.3 | J33: 120.7
B34: =Plate3_RawData_11_29!E306 -> 0.082 | J34: 44.7
A35: 10.6 (A) | B35: =Plate3_RawData_11_29!E307 -> 0.093 | C35: =AVERAGE(B35,B36) -> 0.0995 | D35: =100*(STDEV(B35,B36)/C35) -> 9.2385811 | E35: =C35-$C$2 -> 0.0575 | F35: =(E35-$L$10)/$L$9 -> 55.3 | J35: 159.2
B36: =Plate3_RawData_11_29!E308 -> 0.106 | J36: 56.2
A37: 9.3 (D) | B37: =Plate3_RawData_11_29!E309 -> 0.136 | C37: =AVERAGE(B37,B38) -> 0.143 | D37: =100*(STDEV(B37,B38)/C37) -> 6.9227237 | E37: =C37-$C$2 -> 0.101 | F37: =(E37-$L$10)/$L$9 -> 98.8 | J37: 50.2
B38: =Plate3_RawData_11_29!E310 -> 0.15 | J38: 44.7
A39: 11.2 (A) | B39: =Plate3_RawData_11_29!E311 -> 0.135 | C39: =AVERAGE(B39,B40) -> 0.1335 | D39: =100*(STDEV(B39,B40)/C39) -> 1.589004 | E39: =C39-$C$2 -> 0.0915 | F39: =(E39-$L$10)/$L$9 -> 89.3 | J39: 87.7
B40: =Plate3_RawData_11_29!E312 -> 0.132 | J40: 174.2
A41: 5.4 (C) | B41: =Plate3_RawData_11_29!E313 -> 0.082 | C41: =AVERAGE(B41,B42) -> 0.084 | D41: =100*(STDEV(B41,B42)/C41) -> 3.3671751 | E41: =C41-$C$2 -> 0.042 | F41: =(E41-$L$10)/$L$9 -> 39.8 | J41: 13.7
B42: =Plate3_RawData_11_29!E314 -> 0.086 | J42: 41.7
A43: 5.3 (D) | B43: =Plate3_RawData_11_29!E315 -> 0.188 | C43: =AVERAGE(B43,B44) -> 0.186 | D43: =100*(STDEV(B43,B44)/C43) -> 1.5206597 | E43: =C43-$C$2 -> 0.144 | F43: =(E43-$L$10)/$L$9 -> 141.8 | J43: 37.2
B44: =Plate3_RawData_11_29!E316 -> 0.184 | J44: 90.2
...

Sheet Plate3_RawData_11_29
A2: Software Version | B2: 2.09.1
A4: Experiment File Path: | B4: E:\GT_Metabolomics\TRIG_11_29_24_Plate3.xpt
A5: Protocol File Path: | B5: C:\Users\Public\Documents\Protocols\Schwartz_TRIG.prt
A6: Plate Number | B6: Plate 1
A7: Date | B7: 45625
A8: Time | B8: 0.62763889
A9: Reader Type: | B9: Cytation3
A10: Reader Serial Number: | B10: Unknown
A11: Reading Type | B11: Reader
A13: Procedure Details
A14: Plate Type | B14: 96 WELL PLATE
A15: Eject plate on completion
A16: Read | B16: Absorbance Endpoint
B17: Full Plate
B18: Wavelengths: 500
B19: Read Speed: Normal, Delay: 100 msec, Measurements/Data Point: 8
A21: Layout
C23: 1 | D23: 2 | E23: 3 | F23: 4 | G23: 5 | H23: 6 | I23: 7 | J23: 8 | K23: 9 | L23: 10 | M23: 11 | N23: 12
B24: A | C24: BLK | D24: STD4 | E24: SPL2 | F24: SPL6 | G24: SPL10 | H24: SPL14 | I24: SPL18 | J24: SPL22 | K24: SPL26 | L24: SPL30 | M24: SPL34 | N24: SPL38 | O24: Well ID
D25: 100 | O25: Conc/Dil
B26: B | C26: BLK | D26: STD4 | E26: SPL2 | F26: SPL6 | G26: SPL10 | H26: SPL14 | I26: SPL18 | J26: SPL22 | K26: SPL26 | L26: SPL30 | M26: SPL34 | N26: SPL38 | O26: Well ID
D27: 100 | O27: Conc/Dil
B28: C | C28: STD1 | D28: STD5 | E28: SPL3 | F28: SPL7 | G28: SPL11 | H28: SPL15 | I28: SPL19 | J28: SPL23 | K28: SPL27 | L28: SPL31 | M28: SPL35 | N28: SPL39 | O28: Well ID
C29: 0 | D29: 150 | O29: Conc/Dil
B30: D | C30: STD1 | D30: STD5 | E30: SPL3 | F30: SPL7 | G30: SPL11 | H30: SPL15 | I30: SPL19 | J30: SPL23 | K30: SPL27 | L30: SPL31 | M30: SPL35 | N30: SPL39 | O30: Well ID
C31: 0 | D31: 150 | O31: Conc/Dil
B32: E | C32: STD2 | D32: STD6 | E32: SPL4 | F32: SPL8 | G32: SPL12 | H32: SPL16 | I32: SPL20 | J32: SPL24 | K32: SPL28 | L32: SPL32 | M32: SPL36 | N32: SPL40 | O32: Well ID
C33: 12.5 | D33: 200 | O33: Conc/Dil
B34: F | C34: STD2 | D34: STD6 | E34: SPL4 | F34: SPL8 | G34: SPL12 | H34: SPL16 | I34: SPL20 | J34: SPL24 | K34: SPL28 | L34: SPL32 | M34: SPL36 | N34: SPL40 | O34: Well ID
C35: 12.5 | D35: 200 | O35: Conc/Dil
B36: G | C36: STD3 | D36: SPL1 | E36: SPL5 | F36: SPL9 | G36: SPL13 | H36: SPL17 | I36: SPL21 | J36: SPL25 | K36: SPL29 | L36: SPL33 | M36: SPL37 | N36: SPL41 | O36: Well ID
C37: 50 | O37: Conc/Dil
B38: H | C38: STD3 | D38: SPL1 | E38: SPL5 | F38: SPL9 | G38: SPL13 | H38: SPL17 | I38: SPL21 | J38: SPL25 | K38: SPL29 | L38: SPL33 | M38: SPL37 | N38: SPL41 | O38: Well ID
C39: 50 | O39: Conc/Dil
A41: 500
A42: Actual Temperature: | B42: 26.1
A43: Actual Temperature: | B43: 26.1
A44: Actual Temperature: | B44: 26.1
A45: Actual Temperature: | B45: 26.1
A46: Actual Temperature: | B46: 26.1
...

Sheet Plate2_Analysis_11_27 
A1: Standard | B1: Absorbance | C1: Mean | D1: CV | F1: CorrAbs | H1: Concentation | K1: Data for Plot
A2: Blank | B2: =Plate2_RawData_11_27!E190 -> 0.052 | C2: =AVERAGE(B2,B3) -> 0.0475 | D2: =100*(STDEV(B2,B3)/C2) -> 13.397813 | F2: =C2-$C$2 -> 0 | H2: 0 | K2: 0 | L2: =F4 -> -0.0005
A3: Blank | B3: =Plate2_RawData_11_27!E191 -> 0.043 | K3: 12.5 | L3: =F6 -> 0.015
A4: S0 | B4: =Plate2_RawData_11_27!E274 -> 0.047 | C4: =AVERAGE(B4,B5) -> 0.047 | D4: =100*(STDEV(B4,B5)/C4) -> 0 | F4: =C4-$C$2 -> -0.0005 | H4: 0 | K4: 50 | L4: =F8 -> 0.0475
A5: S0 | B5: =Plate2_RawData_11_27!E275 -> 0.047 | K5: 100 | L5: =F10 -> 0.098
A6: S1 | B6: =Plate2_RawData_11_27!E276 -> 0.056 | C6: =AVERAGE(B6,B7) -> 0.0625 | D6: =100*(STDEV(B6,B7)/C6) -> 14.707821 | F6: =C6-$C$2 -> 0.015 | H6: 12.5 | K6: 150 | L6: =F12 -> 0.144
A7: S1 | B7: =Plate2_RawData_11_27!E277 -> 0.069 | K7: 200 | L7: =F14 -> 0.2045
A8: S3 | B8: =Plate2_RawData_11_27!E278 -> 0.092 | C8: =AVERAGE(B8,B9) -> 0.095 | D8: =100*(STDEV(B8,B9)/C8) -> 4.4659376 | F8: =C8-$C$2 -> 0.0475 | H8: 50
A9: S3 | B9: =Plate2_RawData_11_27!E279 -> 0.098 | K9: Slope | L9: 0.001
A10: S5 | B10: =Plate2_RawData_11_27!E280 -> 0.144 | C10: =AVERAGE(B10,B11) -> 0.1455 | D10: =100*(STDEV(B10,B11)/C10) -> 1.4579521 | F10: =C10-$C$2 -> 0.098 | H10: 100 | K10: Intercept | L10: 0.0008
A11: S5 | B11: =Plate2_RawData_11_27!E281 -> 0.147 | L11: 8
A12: S7 | B12: =Plate2_RawData_11_27!E282 -> 0.182 | C12: =AVERAGE(B12,B13) -> 0.1915 | D12: =100*(STDEV(B12,B13)/C12) -> 7.0156809 | F12: =C12-$C$2 -> 0.144 | H12: 150
A13: S7 | B13: =Plate2_RawData_11_27!E283 -> 0.201
A14: S9 | B14: =Plate2_RawData_11_27!E284 -> 0.241 | C14: =AVERAGE(B14,B15) -> 0.252 | D14: =100*(STDEV(B14,B15)/C14) -> 6.1731544 | F14: =C14-$C$2 -> 0.2045 | H14: 200
A15: S9 | B15: =Plate2_RawData_11_27!E285 -> 0.263
A20: Sample Name | B20: Absorbance | C20: Mean | D20: CV | E20: CorrAbs | F20: Final Concentration | H20: Color Scheme: | J20: Overwinter | K20: Greenhouse
A21: GH_Pool | B21: =Plate2_RawData_11_27!E293 -> 0.193 | C21: =AVERAGE(B21,B22) -> 0.1885 | D21: =100*(STDEV(B21,B22)/C21) -> 3.3761066 | E21: =C21-$C$2 -> 0.141 | F21: =(E21-$L$10)/$L$9 -> 140.2
B22: =Plate2_RawData_11_27!E294 -> 0.184
A23: 12.5 (A) | B23: =Plate2_RawData_11_27!E295 -> 0.138 | C23: =AVERAGE(B23,B24) -> 0.1425 | D23: =100*(STDEV(B23,B24)/C23) -> 4.4659376 | E23: =C23-$C$2 -> 0.095 | F23: =(E23-$L$10)/$L$9 -> 94.2
B24: =Plate2_RawData_11_27!E296 -> 0.147
A25: 6.3 (A) | B25: =Plate2_RawData_11_27!E297 -> 0.087 | C25: =AVERAGE(B25,B26) -> 0.089 | D25: =100*(STDEV(B25,B26)/C25) -> 3.178008 | E25: =C25-$C$2 -> 0.0415 | F25: =(E25-$L$10)/$L$9 -> 40.7
B26: =Plate2_RawData_11_27!E298 -> 0.091
A27: 13.1 (D) | B27: =Plate2_RawData_11_27!E299 -> 0.153 | C27: =AVERAGE(B27,B28) -> 0.1455 | D27: =100*(STDEV(B27,B28)/C27) -> 7.2897606 | E27: =C27-$C$2 -> 0.098 | F27: =(E27-$L$10)/$L$9 -> 97.2 | J27: Timepoint | K27: Label
B28: =Plate2_RawData_11_27!E300 -> 0.138 | J28: Baseline | K28: A
A29: 3.3 (A) | B29: =Plate2_RawData_11_27!E301 -> 0.105 | C29: =AVERAGE(B29,B30) -> 0.104 | D29: =100*(STDEV(B29,B30)/C29) -> 1.3598207 | E29: =C29-$C$2 -> 0.0565 | F29: =(E29-$L$10)/$L$9 -> 55.7 | J29: Cold Dormancy | K29: B
B30: =Plate2_RawData_11_27!E302 -> 0.103 | J30: 3 weeks | K30: C
A31: 14.4 (D) | B31: =Plate2_RawData_11_27!E303 -> 0.115 | C31: =AVERAGE(B31,B32) -> 0.1145 | D31: =100*(STDEV(B31,B32)/C31) -> 0.61756051 | E31: =C31-$C$2 -> 0.067 | F31: =(E31-$L$10)/$L$9 -> 66.2 | J31: 3 months | K31: D
B32: =Plate2_RawData_11_27!E304 -> 0.114
A33: 5.1 (A) | B33: =Plate2_RawData_11_27!E305 -> 0.154 | C33: =AVERAGE(B33,B34) -> 0.156 | D33: =100*(STDEV(B33,B34)/C33) -> 1.8130943 | E33: =C33-$C$2 -> 0.1085 | F33: =(E33-$L$10)/$L$9 -> 107.7
B34: =Plate2_RawData_11_27!E306 -> 0.158
A35: 10.4 (A) | B35: =Plate2_RawData_11_27!E307 -> 0.083 | C35: =AVERAGE(B35,B36) -> 0.1115 | D35: =100*(STDEV(B35,B36)/C35) -> 36.14806 | E35: =C35-$C$2 -> 0.064 | F35: =(E35-$L$10)/$L$9 -> 63.2
B36: =Plate2_RawData_11_27!E308 -> 0.14
A37: 3.1 (D) | B37: =Plate2_RawData_11_27!E309 -> 0.231 | C37: =AVERAGE(B37,B38) -> 0.2275 | D37: =100*(STDEV(B37,B38)/C37) -> 2.1757132 | E37: =C37-$C$2 -> 0.18 | F37: =(E37-$L$10)/$L$9 -> 179.2
B38: =Plate2_RawData_11_27!E310 -> 0.224
A39: 12.2 (A) | B39: =Plate2_RawData_11_27!E311 -> 0.087 | C39: =AVERAGE(B39,B40) -> 0.087 | D39: =100*(STDEV(B39,B40)/C39) -> 0 | E39: =C39-$C$2 -> 0.0395 | F39: =(E39-$L$10)/$L$9 -> 38.7
B40: =Plate2_RawData_11_27!E312 -> 0.087
A41: 13.3 (A) | B41: =Plate2_RawData_11_27!E313 -> 0.148 | C41: =AVERAGE(B41,B42) -> 0.1675 | D41: =100*(STDEV(B41,B42)/C41) -> 16.463979 | E41: =C41-$C$2 -> 0.12 | F41: =(E41-$L$10)/$L$9 -> 119.2
B42: =Plate2_RawData_11_27!E314 -> 0.187
A43: 3.3 (D) | B43: =Plate2_RawData_11_27!E315 -> 0.155 | C43: =AVERAGE(B43,B44) -> 0.169 | D43: =100*(STDEV(B43,B44)/C43) -> 11.715379 | E43: =C43-$C$2 -> 0.1215 | F43: =(E43-$L$10)/$L$9 -> 120.7
B44: =Plate2_RawData_11_27!E316 -> 0.183
...

Sheet Plate2_RawData_11_27
A2: Software Version | B2: 2.09.1
A4: Experiment File Path: | B4: E:\GT_Metabolomics\TRIG_11_27_24_Plate2.xpt
A5: Protocol File Path: | B5: C:\Users\Public\Documents\Protocols\Schwartz_TRIG.prt
A6: Plate Number | B6: Plate 1
A7: Date | B7: 45623
A8: Time | B8: 0.86427083
A9: Reader Type: | B9: Cytation3
A10: Reader Serial Number: | B10: Unknown
A11: Reading Type | B11: Reader
A13: Procedure Details
A14: Plate Type | B14: 96 WELL PLATE
A15: Eject plate on completion
A16: Read | B16: Absorbance Endpoint
B17: Full Plate
B18: Wavelengths: 500
B19: Read Speed: Normal, Delay: 100 msec, Measurements/Data Point: 8
A21: Layout
C23: 1 | D23: 2 | E23: 3 | F23: 4 | G23: 5 | H23: 6 | I23: 7 | J23: 8 | K23: 9 | L23: 10 | M23: 11 | N23: 12
B24: A | C24: BLK | D24: STD4 | E24: SPL2 | F24: SPL6 | G24: SPL10 | H24: SPL14 | I24: SPL18 | J24: SPL22 | K24: SPL26 | L24: SPL30 | M24: SPL34 | N24: SPL38 | O24: Well ID
D25: 100 | O25: Conc/Dil
B26: B | C26: BLK | D26: STD4 | E26: SPL2 | F26: SPL6 | G26: SPL10 | H26: SPL14 | I26: SPL18 | J26: SPL22 | K26: SPL26 | L26: SPL30 | M26: SPL34 | N26: SPL38 | O26: Well ID
D27: 100 | O27: Conc/Dil
B28: C | C28: STD1 | D28: STD5 | E28: SPL3 | F28: SPL7 | G28: SPL11 | H28: SPL15 | I28: SPL19 | J28: SPL23 | K28: SPL27 | L28: SPL31 | M28: SPL35 | N28: SPL39 | O28: Well ID
C29: 0 | D29: 150 | O29: Conc/Dil
B30: D | C30: STD1 | D30: STD5 | E30: SPL3 | F30: SPL7 | G30: SPL11 | H30: SPL15 | I30: SPL19 | J30: SPL23 | K30: SPL27 | L30: SPL31 | M30: SPL35 | N30: SPL39 | O30: Well ID
C31: 0 | D31: 150 | O31: Conc/Dil
B32: E | C32: STD2 | D32: STD6 | E32: SPL4 | F32: SPL8 | G32: SPL12 | H32: SPL16 | I32: SPL20 | J32: SPL24 | K32: SPL28 | L32: SPL32 | M32: SPL36 | N32: SPL40 | O32: Well ID
C33: 12.5 | D33: 200 | O33: Conc/Dil
B34: F | C34: STD2 | D34: STD6 | E34: SPL4 | F34: SPL8 | G34: SPL12 | H34: SPL16 | I34: SPL20 | J34: SPL24 | K34: SPL28 | L34: SPL32 | M34: SPL36 | N34: SPL40 | O34: Well ID
C35: 12.5 | D35: 200 | O35: Conc/Dil
B36: G | C36: STD3 | D36: SPL1 | E36: SPL5 | F36: SPL9 | G36: SPL13 | H36: SPL17 | I36: SPL21 | J36: SPL25 | K36: SPL29 | L36: SPL33 | M36: SPL37 | N36: SPL41 | O36: Well ID
C37: 50 | O37: Conc/Dil
B38: H | C38: STD3 | D38: SPL1 | E38: SPL5 | F38: SPL9 | G38: SPL13 | H38: SPL17 | I38: SPL21 | J38: SPL25 | K38: SPL29 | L38: SPL33 | M38: SPL37 | N38: SPL41 | O38: Well ID
C39: 50 | O39: Conc/Dil
A41: 500
A42: Actual Temperature: | B42: 26.9
A43: Actual Temperature: | B43: 26.9
A44: Actual Temperature: | B44: 26.9
A45: Actual Temperature: | B45: 26.9
A46: Actual Temperature: | B46: 26.9
...

Sheet Plate1_Analysis_11_27
A1: Standard | B1: Absorbance | C1: Mean | D1: CV | F1: CorrAbs | H1: Concentation | K1: Data for Plot
A2: Blank | B2: =Plate1_RawData_11_27!E291 -> 0.043 | C2: =AVERAGE(B2,B3) -> 0.043 | D2: =100*(STDEV(B2,B3)/C2) -> 0 | F2: =C2-$C$2 -> 0 | H2: 0 | K2: 0 | L2: =F4 -> 0.001
A3: Blank | B3: =Plate1_RawData_11_27!E292 -> 0.043 | K3: 12.5 | L3: =F6 -> 0.013
A4: S0 | B4: =Plate1_RawData_11_27!E341 -> 0.043 | C4: =AVERAGE(B4,B5) -> 0.044 | D4: =100*(STDEV(B4,B5)/C4) -> 3.2141217 | E4: Subsituted for value in G8, higher than normal | F4: =C4-$C$2 -> 0.001 | H4: 0 | K4: 50 | L4: =F8 -> 0.0495
A5: S0 | B5: =Plate1_RawData_11_27!E342 -> 0.045 | K5: 100 | L5: =F10 -> 0.0995
A6: S1 | B6: =Plate1_RawData_11_27!E377 -> 0.056 | C6: =AVERAGE(B6,B7) -> 0.056 | D6: =100*(STDEV(B6,B7)/C6) -> 0 | F6: =C6-$C$2 -> 0.013 | H6: 12.5 | K6: 150 | L6: =F12 -> 0.169
A7: S1 | B7: =Plate1_RawData_11_27!E378 -> 0.056 | K7: 200 | L7: =F14 -> 0.243
A8: S3 | B8: =Plate1_RawData_11_27!E379 -> 0.088 | C8: =AVERAGE(B8,B9) -> 0.0925 | D8: =100*(STDEV(B8,B9)/C8) -> 6.8799579 | F8: =C8-$C$2 -> 0.0495 | H8: 50
A9: S3 | B9: =Plate1_RawData_11_27!E380 -> 0.097 | K9: Slope | L9: 0.0012
A10: S5 | B10: =Plate1_RawData_11_27!E381 -> 0.14 | C10: =AVERAGE(B10,B11) -> 0.1425 | D10: =100*(STDEV(B10,B11)/C10) -> 2.4810764 | F10: =C10-$C$2 -> 0.0995 | H10: 100 | K10: Intercept | L10: 0.006
A11: S5 | B11: =Plate1_RawData_11_27!E382 -> 0.145
A12: S7 | B12: =Plate1_RawData_11_27!E383 -> 0.206 | C12: =AVERAGE(B12,B13) -> 0.212 | D12: =100*(STDEV(B12,B13)/C12) -> 4.0024912 | F12: =C12-$C$2 -> 0.169 | H12: 150
A13: S7 | B13: =Plate1_RawData_11_27!E384 -> 0.218
A14: S9 | B14: =Plate1_RawData_11_27!E385 -> 0.321 | C14: =AVERAGE(B14,B15) -> 0.286 | D14: =100*(STDEV(B14,B15)/C14) -> 17.306809 | F14: =C14-$C$2 -> 0.243 | H14: 200
A15: S9 | B15: =Plate1_RawData_11_27!E386 -> 0.251
A20: Sample Name | B20: Absorbance | C20: Mean | D20: CV | E20: CorrAbs | F20: Final Concentration | H20: Color Scheme: | J20: Overwinter | K20: Greenhouse
A21: GH_Pool | B21: =Plate1_RawData_11_27!E293 -> 0.149 | C21: =AVERAGE(B21,B22) -> 0.1585 | D21: =100*(STDEV(B21,B22)/C21) -> 8.4763589 | E21: =C21-$C$2 -> 0.1155 | F21: =(E21-$L$10)/$L$9 -> 91.25
B22: =Plate1_RawData_11_27!E294 -> 0.168
A23: 10.1 (A) | B23: =Plate1_RawData_11_27!E295 -> 0.113 | C23: =AVERAGE(B23,B24) -> 0.116 | D23: =100*(STDEV(B23,B24)/C23) -> 3.6574489 | E23: =C23-$C$2 -> 0.073 | F23: =(E23-$L$10)/$L$9 -> 55.833333
B24: =Plate1_RawData_11_27!E296 -> 0.119
A25: 15.2 (A) | B25: =Plate1_RawData_11_27!E297 -> 0.108 | C25: =AVERAGE(B25,B26) -> 0.1095 | D25: =100*(STDEV(B25,B26)/C25) -> 1.9372789 | E25: =C25-$C$2 -> 0.0665 | F25: =(E25-$L$10)/$L$9 -> 50.416667
B26: =Plate1_RawData_11_27!E298 -> 0.111
A27: 5.2 (D) | B27: =Plate1_RawData_11_27!E299 -> 0.043 | C27: =AVERAGE(B27,B28) -> 0.043 | D27: =100*(STDEV(B27,B28)/C27) -> 0 | E27: =C27-$C$2 -> 0 | F27: =(E27-$L$10)/$L$9 -> -5 | J27: Timepoint | K27: Label
B28: =Plate1_RawData_11_27!E300 -> 0.043 | J28: Baseline | K28: A
A29: 11.1 (A) | B29: =Plate1_RawData_11_27!E301 -> 0.114 | C29: =AVERAGE(B29,B30) -> 0.122 | D29: =100*(STDEV(B29,B30)/C29) -> 9.2735316 | E29: =C29-$C$2 -> 0.079 | F29: =(E29-$L$10)/$L$9 -> 60.833333 | J29: Cold Dormancy | K29: B
B30: =Plate1_RawData_11_27!E302 -> 0.13 | J30: 3 weeks | K30: C
A31: 10.1 (D) | B31: =Plate1_RawData_11_27!E303 -> 0.053 | C31: =AVERAGE(B31,B32) -> 0.056 | D31: =100*(STDEV(B31,B32)/C31) -> 7.5761441 | E31: =C31-$C$2 -> 0.013 | F31: =(E31-$L$10)/$L$9 -> 5.8333333 | J31: 3 months | K31: D
B32: =Plate1_RawData_11_27!E304 -> 0.059
A33: 12.5 (A) | B33: =Plate1_RawData_11_27!E305 -> 0.215 | C33: =AVERAGE(B33,B34) -> 0.172 | D33: =100*(STDEV(B33,B34)/C33) -> 35.355339 | E33: =C33-$C$2 -> 0.129 | F33: =(E33-$L$10)/$L$9 -> 102.5
B34: =Plate1_RawData_11_27!E306 -> 0.129
A35: 13.3 (A) | B35: =Plate1_RawData_11_27!E307 -> 0.162 | C35: =AVERAGE(B35,B36) -> 0.175 | D35: =100*(STDEV(B35,B36)/C35) -> 10.505586 | E35: =C35-$C$2 -> 0.132 | F35: =(E35-$L$10)/$L$9 -> 105
B36: =Plate1_RawData_11_27!E308 -> 0.188
A37: 9.3 (D) | B37: =Plate1_RawData_11_27!E309 -> 0.152 | C37: =AVERAGE(B37,B38) -> 0.159 | D37: =100*(STDEV(B37,B38)/C37) -> 6.2260974 | E37: =C37-$C$2 -> 0.116 | F37: =(E37-$L$10)/$L$9 -> 91.666667
B38: =Plate1_RawData_11_27!E310 -> 0.166
A39: 10.5 (A) | B39: =Plate1_RawData_11_27!E311 -> 0.108 | C39: =AVERAGE(B39,B40) -> 0.1125 | D39: =100*(STDEV(B39,B40)/C39) -> 5.6568542 | E39: =C39-$C$2 -> 0.0695 | F39: =(E39-$L$10)/$L$9 -> 52.916667
B40: =Plate1_RawData_11_27!E312 -> 0.117
A41: 15.2 (C) | B41: =Plate1_RawData_11_27!E313 -> 0.067 | C41: =AVERAGE(B41,B42) -> 0.0655 | D41: =100*(STDEV(B41,B42)/C41) -> 3.238657 | E41: =C41-$C$2 -> 0.0225 | F41: =(E41-$L$10)/$L$9 -> 13.75
B42: =Plate1_RawData_11_27!E314 -> 0.064
A43: 11.1 (D) | B43: =Plate1_RawData_11_27!E315 -> 0.145 | C43: =AVERAGE(B43,B44) -> 0.1385 | D43: =100*(STDEV(B43,B44)/C43) -> 6.6371034 | E43: =C43-$C$2 -> 0.0955 | F43: =(E43-$L$10)/$L$9 -> 74.583333
B44: =Plate1_RawData_11_27!E316 -> 0.132
...

Sheet Plate1_RawData_11_27
A2: Software Version | B2: 2.09.1
A4: Experiment File Path: | B4: E:\GT_Metabolomics\TRIG_11_27_24_Plate1.xpt
A5: Protocol File Path:
A6: Plate Number | B6: Plate 1
A7: Date | B7: 45623
A8: Time | B8: 0.76060185
A9: Reader Type: | B9: Cytation3
A10: Reader Serial Number: | B10: Unknown
A11: Reading Type | B11: Reader
A13: Procedure Details
A14: Plate Type | B14: 96 WELL PLATE
A15: Eject plate on completion
A16: Read | B16: Absorbance Endpoint
B17: Full Plate
B18: Wavelengths: 500
B19: Read Speed: Normal, Delay: 100 msec, Measurements/Data Point: 8
A21: Layout
C23: 1 | D23: 2 | E23: 3 | F23: 4 | G23: 5 | H23: 6 | I23: 7 | J23: 8 | K23: 9 | L23: 10 | M23: 11 | N23: 12
B24: A | C24: BLK | D24: STD4 | E24: SPL2 | F24: SPL6 | G24: SPL10 | H24: SPL14 | I24: SPL18 | J24: SPL22 | K24: SPL26 | L24: SPL30 | M24: SPL34 | N24: SPL38 | O24: Well ID
D25: 100 | O25: Conc/Dil
B26: B | C26: BLK | D26: STD4 | E26: SPL2 | F26: SPL6 | G26: SPL10 | H26: SPL14 | I26: SPL18 | J26: SPL22 | K26: SPL26 | L26: SPL30 | M26: SPL34 | N26: SPL38 | O26: Well ID
D27: 100 | O27: Conc/Dil
B28: C | C28: STD1 | D28: STD5 | E28: SPL3 | F28: SPL7 | G28: SPL11 | H28: SPL15 | I28: SPL19 | J28: SPL23 | K28: SPL27 | L28: SPL31 | M28: SPL35 | N28: SPL39 | O28: Well ID
C29: 0 | D29: 150 | O29: Conc/Dil
B30: D | C30: STD1 | D30: STD5 | E30: SPL3 | F30: SPL7 | G30: SPL11 | H30: SPL15 | I30: SPL19 | J30: SPL23 | K30: SPL27 | L30: SPL31 | M30: SPL35 | N30: SPL39 | O30: Well ID
C31: 0 | D31: 150 | O31: Conc/Dil
B32: E | C32: STD2 | D32: STD6 | E32: SPL4 | F32: SPL8 | G32: SPL12 | H32: SPL16 | I32: SPL20 | J32: SPL24 | K32: SPL28 | L32: SPL32 | M32: SPL36 | N32: SPL40 | O32: Well ID
C33: 12.5 | D33: 200 | O33: Conc/Dil
B34: F | C34: STD2 | D34: STD6 | E34: SPL4 | F34: SPL8 | G34: SPL12 | H34: SPL16 | I34: SPL20 | J34: SPL24 | K34: SPL28 | L34: SPL32 | M34: SPL36 | N34: SPL40 | O34: Well ID
C35: 12.5 | D35: 200 | O35: Conc/Dil
B36: G | C36: STD3 | D36: SPL1 | E36: SPL5 | F36: SPL9 | G36: SPL13 | H36: SPL17 | I36: SPL21 | J36: SPL25 | K36: SPL29 | L36: SPL33 | M36: SPL37 | N36: SPL41 | O36: Well ID
C37: 50 | O37: Conc/Dil
B38: H | C38: STD3 | D38: SPL1 | E38: SPL5 | F38: SPL9 | G38: SPL13 | H38: SPL17 | I38: SPL21 | J38: SPL25 | K38: SPL29 | L38: SPL33 | M38: SPL37 | N38: SPL41 | O38: Well ID
C39: 50 | O39: Conc/Dil
A41: 500
A42: Actual Temperature: | B42: 26.8
A43: Actual Temperature: | B43: 26.8
A44: Actual Temperature: | B44: 26.8
A45: Actual Temperature: | B45: 26.8
A46: Actual Temperature: | B46: 26.8
...

Sheet TRIG_11_07_24_RawData
A2: Software Version | B2: 2.09.1
A4: Experiment File Path: | B4: E:\GT_Metabolomics\TRIG_11_07_24_Optimization.xpt
A5: Protocol File Path: | B5: C:\Users\Public\Documents\Protocols\Schwartz_TRIG.prt
A6: Plate Number | B6: Plate 1
A7: Date | B7: 45603
A8: Time | B8: 0.58288194
A9: Reader Type: | B9: Cytation3
A10: Reader Serial Number: | B10: Unknown
A11: Reading Type | B11: Reader
A13: Procedure Details
A14: Plate Type | B14: 96 WELL PLATE
A15: Eject plate on completion
A16: Read | B16: Absorbance Endpoint
B17: Random
B18: Wavelengths: 500
B19: Read Speed: Normal, Delay: 100 msec, Measurements/Data Point: 8
A21: Layout
C23: 1 | D23: 2 | E23: 3 | F23: 4 | G23: 5 | H23: 6 | I23: 7 | J23: 8 | K23: 9 | L23: 10 | M23: 11 | N23: 12
B24: A | C24: BLK | D24: STD4 | E24: SPL2 | O24: Well ID
D25: 100 | O25: Conc/Dil
B26: B | C26: BLK | D26: STD4 | E26: SPL2 | O26: Well ID
D27: 100 | O27: Conc/Dil
B28: C | C28: STD1 | D28: STD5 | E28: SPL3 | O28: Well ID
C29: 0 | D29: 150 | O29: Conc/Dil
B30: D | C30: STD1 | D30: STD5 | E30: SPL3 | O30: Well ID
C31: 0 | D31: 150 | O31: Conc/Dil
B32: E | C32: STD2 | D32: STD6 | E32: SPL4 | O32: Well ID
C33: 12.5 | D33: 200 | O33: Conc/Dil
B34: F | C34: STD2 | D34: STD6 | E34: SPL4 | O34: Well ID
C35: 12.5 | D35: 200 | O35: Conc/Dil
B36: G | C36: STD3 | D36: SPL1 | E36: SPL5 | O36: Well ID
C37: 50 | O37: Conc/Dil
B38: H | C38: STD3 | D38: SPL1 | E38: SPL5 | O38: Well ID
C39: 50 | O39: Conc/Dil
A41: 500
A42: Actual Temperature: | B42: 25.9
A43: Actual Temperature: | B43: 25.9
A44: Actual Temperature: | B44: 25.9
A45: Actual Temperature: | B45: 25.9
A46: Actual Temperature: | B46: 25.9
...

Sheet TRIG_11_07_24_Analysis 
A1: Standard | B1: Absorbance | C1: Mean | D1: CV | F1: CorrAbs | H1: Concentation | K1: Data for Plot
A2: Blank | B2: =TRIG_11_07_24_RawData!E118 -> 0.046 | C2: =AVERAGE(B2,B3) -> 0.045 | D2: =100*(STDEV(B2,B3)/C2) -> 3.1426968 | F2: =C2-$C$2 -> 0 | H2: 0 | K2: 0 | L2: =F4 -> 0.0005
A3: Blank | B3: =TRIG_11_07_24_RawData!E119 -> 0.044 | K3: 12.5 | L3: =F6 -> 0.015
A4: S0 | B4: =TRIG_11_07_24_RawData!E130 -> 0.048 | C4: =AVERAGE(B4,B5) -> 0.0455 | D4: =100*(STDEV(B4,B5)/C4) -> 7.7704042 | F4: =C4-$C$2 -> 0.0005 | H4: 0 | K4: 50 | L4: =F8 -> 0.06
A5: S0 | B5: =TRIG_11_07_24_RawData!E131 -> 0.043 | K5: 100 | L5: =F10 -> 0.0925
A6: S1 | B6: =TRIG_11_07_24_RawData!E132 -> 0.056 | C6: =AVERAGE(B6,B7) -> 0.06 | D6: =100*(STDEV(B6,B7)/C6) -> 9.4280904 | F6: =C6-$C$2 -> 0.015 | H6: 12.5 | K6: 150 | L6: =F12 -> 0.169
A7: S1 | B7: =TRIG_11_07_24_RawData!E133 -> 0.064 | K7: 200 | L7: =F14 -> 0.2305
A8: S3 | B8: =TRIG_11_07_24_RawData!E134 -> 0.102 | C8: =AVERAGE(B8,B9) -> 0.105 | D8: =100*(STDEV(B8,B9)/C8) -> 4.0406102 | F8: =C8-$C$2 -> 0.06 | H8: 50
A9: S3 | B9: =TRIG_11_07_24_RawData!E135 -> 0.108 | K9: Slope | L9: 0.0011
A10: S5 | B10: =TRIG_11_07_24_RawData!E136 -> 0.135 | C10: =AVERAGE(B10,B11) -> 0.1375 | D10: =100*(STDEV(B10,B11)/C10) -> 2.5712974 | F10: =C10-$C$2 -> 0.0925 | H10: 100 | K10: Intercept | L10: 0.0018
A11: S5 | B11: =TRIG_11_07_24_RawData!E137 -> 0.14
A12: S7 | B12: =TRIG_11_07_24_RawData!E138 -> 0.214 | C12: =AVERAGE(B12,B13) -> 0.214 | D12: =100*(STDEV(B12,B13)/C12) -> 0 | F12: =C12-$C$2 -> 0.169 | H12: 150
A13: S7 | B13: =TRIG_11_07_24_RawData!E139 -> 0.214
A14: S9 | B14: =TRIG_11_07_24_RawData!E140 -> 0.258 | C14: =AVERAGE(B14,B15) -> 0.2755 | D14: =100*(STDEV(B14,B15)/C14) -> 8.9832077 | F14: =C14-$C$2 -> 0.2305 | H14: 200
A15: S9 | B15: =TRIG_11_07_24_RawData!E141 -> 0.293
A20: Sample Name | B20: Absorbance | C20: Mean | D20: CV | E20: CorrAbs | F20: Final Concentration | H20: Color Scheme: | J20: Overwinter | K20: Greenhouse
A21: GH_Pool | B21: =TRIG_11_07_24_RawData!E120 -> 0.162 | C21: =AVERAGE(B21,B22) -> 0.1615 | D21: =100*(STDEV(B21,B22)/C21) -> 0.43783702 | E21: =C21-$C$2 -> 0.1165 | F21: =(E21-$L$10)/$L$9 -> 104.27273
B22: =TRIG_11_07_24_RawData!E121 -> 0.161
A23: 2.4 (A) | B23: =TRIG_11_07_24_RawData!E122 -> 0.092 | C23: =AVERAGE(B23,B24) -> 0.092 | D23: =100*(STDEV(B23,B24)/C23) -> 0 | E23: =C23-$C$2 -> 0.047 | F23: =(E23-$L$10)/$L$9 -> 41.090909
B24: =TRIG_11_07_24_RawData!E123 -> 0.092
A25: 2.2(A) | B25: =TRIG_11_07_24_RawData!E124 -> 0.123 | C25: =AVERAGE(B25,B26) -> 0.1295 | D25: =100*(STDEV(B25,B26)/C25) -> 7.0983692 | E25: =C25-$C$2 -> 0.0845 | F25: =(E25-$L$10)/$L$9 -> 75.181818 | G25: Not enough for duplicate (7uL added to second well opposed to 10uL)
B26: =TRIG_11_07_24_RawData!E125 -> 0.136
A27: OW_Pool | B27: =TRIG_11_07_24_RawData!E126 -> 0.099 | C27: =AVERAGE(B27,B28) -> 0.096 | D27: =100*(STDEV(B27,B28)/C27) -> 4.4194174 | E27: =C27-$C$2 -> 0.051 | F27: =(E27-$L$10)/$L$9 -> 44.727273 | J27: Timepoint | K27: Label
B28: =TRIG_11_07_24_RawData!E127 -> 0.093 | J28: Baseline | K28: A
A29: 5.2 (D) | B29: =TRIG_11_07_24_RawData!E128 -> 0.252 | C29: =AVERAGE(B29,B30) -> 0.2535 | D29: =100*(STDEV(B29,B30)/C29) -> 0.83681276 | E29: =C29-$C$2 -> 0.2085 | F29: =(E29-$L$10)/$L$9 -> 187.90909 | J29: Cold Dormancy | K29: B
B30: =TRIG_11_07_24_RawData!E129 -> 0.255 | J30: 3 weeks | K30: C
J31: 3 months | K31: D

Sheet TRIG_10_24_24_RawData
A2: Software Version | B2: 2.09.1
A4: Experiment File Path:
A5: Protocol File Path:
A6: Plate Number | B6: Plate 1
A7: Date | B7: 45589
A8: Time | B8: 0.72211806
A9: Reader Type: | B9: Cytation3
A10: Reader Serial Number: | B10: 13081218
A11: Reading Type | B11: Reader
A13: Procedure Details
A14: Plate Type | B14: 96 WELL PLATE
A15: Eject plate on completion
A16: Read | B16: Absorbance Endpoint
B17: Full Plate
B18: Wavelengths: 500
B19: Read Speed: Normal, Delay: 100 msec, Measurements/Data Point: 8
A21: Layout
C23: 1 | D23: 2 | E23: 3 | F23: 4 | G23: 5 | H23: 6 | I23: 7 | J23: 8 | K23: 9 | L23: 10 | M23: 11 | N23: 12
B24: A | D24: STD4 | E24: SPL2 | F24: SPL6 | G24: SPL10 | H24: SPL14 | O24: Well ID
D25: 100 | O25: Conc/Dil
B26: B | D26: STD4 | E26: SPL2 | F26: SPL6 | G26: SPL10 | H26: SPL14 | O26: Well ID
D27: 100 | O27: Conc/Dil
B28: C | C28: STD1 | D28: STD5 | E28: SPL3 | F28: SPL7 | G28: SPL11 | H28: SPL15 | O28: Well ID
C29: 0 | D29: 150 | O29: Conc/Dil
B30: D | C30: STD1 | D30: STD5 | E30: SPL3 | F30: SPL7 | G30: SPL11 | H30: SPL15 | O30: Well ID
C31: 0 | D31: 150 | O31: Conc/Dil
B32: E | C32: STD2 | D32: STD6 | E32: SPL4 | F32: SPL8 | G32: SPL12 | H32: SPL16 | O32: Well ID
C33: 12.5 | D33: 200 | O33: Conc/Dil
B34: F | C34: STD2 | D34: STD6 | E34: SPL4 | F34: SPL8 | G34: SPL12 | H34: SPL16 | O34: Well ID
C35: 12.5 | D35: 200 | O35: Conc/Dil
B36: G | C36: STD3 | D36: SPL1 | E36: SPL5 | F36: SPL9 | G36: SPL13 | H36: SPL17 | O36: Well ID
C37: 50 | O37: Conc/Dil
B38: H | C38: STD3 | D38: SPL1 | E38: SPL5 | F38: SPL9 | G38: SPL13 | H38: SPL17 | O38: Well ID
C39: 50 | O39: Conc/Dil
A41: 500
A42: Actual Temperature: | B42: 26.1
A43: Actual Temperature: | B43: 26.1
A44: Actual Temperature: | B44: 26.1
A45: Actual Temperature: | B45: 26.1
A46: Actual Temperature: | B46: 26.1
...

Sheet TRIG_10_24_24_Analysis
A1: Standard | B1: Absorbance | C1: Mean | D1: CV | F1: CorrAbs | H1: Concentation | K1: Data for Plot
A2: S0 | B2: =TRIG_10_24_24_RawData!E83 -> 0.047 | C2: =AVERAGE(B2,B3) -> 0.0465 | D2: =100*(STDEV(B2,B3)/C2) -> 1.5206597 | F2: =C2-$C$2 -> 0 | H2: 0 | K2: 0 | L2: =F2 -> 0
A3: S0 | B3: =TRIG_10_24_24_RawData!E84 -> 0.046 | K3: 12.5 | L3: =F4 -> 0.0425
A4: S1 | B4: =TRIG_10_24_24_RawData!E85 -> 0.085 | C4: =AVERAGE(B4,B5) -> 0.089 | D4: =100*(STDEV(B4,B5)/C4) -> 6.356016 | F4: =C4-$C$2 -> 0.0425 | H4: 12.5 | K4: 50 | L4: =F6 -> 0.1465
A5: S1 | B5: =TRIG_10_24_24_RawData!E86 -> 0.093 | K5: 100 | L5: =F8 -> 0.288
A6: S3 | B6: =TRIG_10_24_24_RawData!E87 -> 0.192 | C6: =AVERAGE(B6,B7) -> 0.193 | D6: =100*(STDEV(B6,B7)/C6) -> 0.73275314 | F6: =C6-$C$2 -> 0.1465 | H6: 50 | K6: 150 | L6: =F10 -> 0.427
A7: S3 | B7: =TRIG_10_24_24_RawData!E88 -> 0.194 | K7: 200 | L7: =F12 -> 0.5675
A8: S5 | B8: =TRIG_10_24_24_RawData!E89 -> 0.33 | C8: =AVERAGE(B8,B9) -> 0.3345 | D8: =100*(STDEV(B8,B9)/C8) -> 1.9025295 | F8: =C8-$C$2 -> 0.288 | H8: 100
A9: S5 | B9: =TRIG_10_24_24_RawData!E90 -> 0.339 | K9: Slope | L9: 0.0028
A10: S7 | B10: =TRIG_10_24_24_RawData!E91 -> 0.469 | C10: =AVERAGE(B10,B11) -> 0.4735 | D10: =100*(STDEV(B10,B11)/C10) -> 1.3440256 | F10: =C10-$C$2 -> 0.427 | H10: 150 | K10: Intercept | L10: 0.0043
A11: S7 | B11: =TRIG_10_24_24_RawData!E92 -> 0.478
A12: S9 | B12: =TRIG_10_24_24_RawData!E93 -> 0.597 | C12: =AVERAGE(B12,B13) -> 0.614 | D12: =100*(STDEV(B12,B13)/C12) -> 3.915575 | F12: =C12-$C$2 -> 0.5675 | H12: 200
A13: S9 | B13: =TRIG_10_24_24_RawData!E94 -> 0.631
A15: Sample Name | B15: Absorbance | C15: Mean | D15: CV | E15: CorrAbs | F15: Concentration | H15: Color Scheme: | J15: Overwinter | K15: Greenhouse
A16: GH_Pool | B16: =TRIG_10_24_24_RawData!E140 -> 0.397 | C16: =AVERAGE(B16,B17) -> 0.4095 | D16: =100*(STDEV(B16,B17)/C16) -> 4.3168912 | E16: =C16-$C$2 -> 0.363 | F16: =(E16-$L$10)/$L$9 -> 128.10714 | H16: Samples with abnornal absorbance and concentrations highlighted in yellow
B17: =TRIG_10_24_24_RawData!E141 -> 0.422 | H17: Samples off curve indicated by orange highlight
A18: GH_Pool_1:2 | B18: =TRIG_10_24_24_RawData!E142 -> 0.216 | C18: =AVERAGE(B18,B19) -> 0.227 | D18: =100*(STDEV(B18,B19)/C18) -> 6.8530173 | E18: =C18-$C$2 -> 0.1805 | F18: =(E18-$L$10)/$L$9 -> 62.928571 | G18: =F18*2 -> 125.85714
B19: =TRIG_10_24_24_RawData!E143 -> 0.238
A20: GH_Pool_1:4 | B20: =TRIG_10_24_24_RawData!E144 -> 0.132 | C20: =AVERAGE(B20,B21) -> 0.1185 | D20: =100*(STDEV(B20,B21)/C20) -> 16.111294 | E20: =C20-$C$2 -> 0.072 | F20: =(E20-$L$10)/$L$9 -> 24.178571 | G20: Not enough for duplicate (7uL added to second well opposed to 10uL)
B21: =TRIG_10_24_24_RawData!E145 -> 0.105
A22: OW_Pool | B22: =TRIG_10_24_24_RawData!E146 -> 0.213 | C22: =AVERAGE(B22,B23) -> 0.2135 | D22: =100*(STDEV(B22,B23)/C22) -> 0.33119756 | E22: =C22-$C$2 -> 0.167 | F22: =(E22-$L$10)/$L$9 -> 58.107143 | J22: Timepoint | K22: Label
B23: =TRIG_10_24_24_RawData!E147 -> 0.214 | J23: Baseline | K23: A
A24: OW_Pool_1:2 | B24: =TRIG_10_24_24_RawData!E148 -> 0.122 | C24: =AVERAGE(B24,B25) -> 0.122 | D24: =100*(STDEV(B24,B25)/C24) -> 0 | E24: =C24-$C$2 -> 0.0755 | F24: =(E24-$L$10)/$L$9 -> 25.428571 | G24: =F24*2 -> 50.857143 | J24: Cold Dormancy | K24: B
B25: =TRIG_10_24_24_RawData!E149 -> 0.122 | J25: 3 weeks | K25: C
A26: OW_Pool_1:4 | B26: =TRIG_10_24_24_RawData!E150 -> 0.079 | C26: =AVERAGE(B26,B27) -> 0.0625 | D26: =100*(STDEV(B26,B27)/C26) -> 37.335238 | E26: =C26-$C$2 -> 0.016 | F26: =(E26-$L$10)/$L$9 -> 4.1785714 | G26: Not enough for duplicate | J26: 3 months | K26: D
B27: =TRIG_10_24_24_RawData!E151 -> 0.046
A28: 3.3 (C) | B28: =TRIG_10_24_24_RawData!E152 -> 0.524 | C28: =AVERAGE(B28,B29) -> 0.504 | D28: =100*(STDEV(B28,B29)/C28) -> 5.6119586 | E28: =C28-$C$2 -> 0.4575 | F28: =(E28-$L$10)/$L$9 -> 161.85714
B29: =TRIG_10_24_24_RawData!E153 -> 0.484
A30: 5.2 (D) | B30: =TRIG_10_24_24_RawData!E154 -> 0.694 | C30: =AVERAGE(B30,B31) -> 0.7165 | D30: =100*(STDEV(B30,B31)/C30) -> 4.4410056 | E30: =C30-$C$2 -> 0.67 | F30: =(E30-$L$10)/$L$9 -> 237.75 | G30: Falls off the curve
B31: =TRIG_10_24_24_RawData!E155 -> 0.739 | G31: These four wells make me suspicious that in a hurry I accidentally added plasma from two samples in one well
A32: 3.3 (D) | B32: =TRIG_10_24_24_RawData!E156 -> 0.046 | C32: =AVERAGE(B32,B33) -> 0.0465 | D32: =100*(STDEV(B32,B33)/C32) -> 1.5206597 | E32: =C32-$C$2 -> 0 | F32: =(E32-$L$10)/$L$9 -> -1.5357143 | G32: Values similar to blank, unsure what happened here, likely no plasma was added to well
B33: =TRIG_10_24_24_RawData!E157 -> 0.047
A34: 5.2 (C) | B34: =TRIG_10_24_24_RawData!E158 -> 0.283 | C34: =AVERAGE(B34,B35) -> 0.301 | D34: =100*(STDEV(B34,B35)/C34) -> 8.4570911 | E34: =C34-$C$2 -> 0.2545 | F34: =(E34-$L$10)/$L$9 -> 89.357143
B35: =TRIG_10_24_24_RawData!E159 -> 0.319
A36: 6.4 (D) | B36: =TRIG_10_24_24_RawData!E160 -> 0.098 | C36: =AVERAGE(B36,B37) -> 0.102 | D36: =100*(STDEV(B36,B37)/C36) -> 5.5459355 | E36: =C36-$C$2 -> 0.0555 | F36: =(E36-$L$10)/$L$9 -> 18.285714
B37: =TRIG_10_24_24_RawData!E161 -> 0.106
A38: 15.5 (D) | B38: =TRIG_10_24_24_RawData!E162 -> 0.233 | C38: =AVERAGE(B38,B39) -> 0.226 | D38: =100*(STDEV(B38,B39)/C38) -> 4.3803075 | E38: =C38-$C$2 -> 0.1795 | F38: =(E38-$L$10)/$L$9 -> 62.571429
B39: =TRIG_10_24_24_RawData!E163 -> 0.219
A40: 5.3 (D) | B40: =TRIG_10_24_24_RawData!E164 -> 0.468 | C40: =AVERAGE(B40,B41) -> 0.497 | D40: =100*(STDEV(B40,B41)/C40) -> 8.2519504 | E40: =C40-$C$2 -> 0.4505 | F40: =(E40-$L$10)/$L$9 -> 159.35714
B41: =TRIG_10_24_24_RawData!E165 -> 0.526
...

Sheet TRIG_10_10_24_Analysis
A1: Standard | B1: Absorbance | C1: Mean | D1: CV | F1: CorrAbs | H1: Concentation
A2: Blank | B2: =TRIG_10_10_24_RawData!E86 -> 0.072 | C2: =AVERAGE(B2,B3) -> 0.0635 | D2: =100*(STDEV(B2,B3)/C2) -> 18.930418 | F2: =C2-$C$2 -> 0 | H2: 0
A3: Blank | B3: =TRIG_10_10_24_RawData!E87 -> 0.055 | K3: Data for Plot | N3: Greenhouse | Q3: Overwinter
A4: STD_0 | B4: =TRIG_10_10_24_RawData!E108 -> 0.055 | C4: =AVERAGE(B4,B5) -> 0.0535 | D4: =100*(STDEV(B4,B5)/C4) -> 3.9650848 | F4: =C4-$C$4 -> 0 | H4: 0 | K4: 0 | L4: 0 | N4: 115 | O4: 115 | Q4: 49 | R4: 0.1455
A5: STD_0 | B5: =TRIG_10_10_24_RawData!E109 -> 0.052 | K5: 50 | L5: 0.161 | N5: 94 | O5: 0.131 | Q5: 15 | R5: 0.045
A6: STD_1 | B6: =TRIG_10_10_24_RawData!E110 -> 0.216 | C6: =AVERAGE(B6,B7) -> 0.2145 | D6: =100*(STDEV(B6,B7)/C6) -> 0.98896053 | F6: =C6-$C$4 -> 0.161 | H6: 50 | K6: 100 | L6: 0.3 | N6: 19 | O6: 0.058 | Q6: 4 | R6: 0.0135
A7: STD_1 | B7: =TRIG_10_10_24_RawData!E111 -> 0.213 | K7: 150 | L7: 0.4855 | N7: 6 | O7: 0.0195
A8: STD_2 | B8: =TRIG_10_10_24_RawData!E112 -> 0.353 | C8: =AVERAGE(B8,B9) -> 0.3535 | D8: =100*(STDEV(B8,B9)/C8) -> 0.20003021 | F8: =C8-$C$4 -> 0.3 | H8: 100 | K8: 200 | L8: 0.562
A9: STD_2 | B9: =TRIG_10_10_24_RawData!E113 -> 0.354 | K9: Slope | L9: 0.003 | O9: 3.3 | P9: 0.4665 | Q9: 160.17241
A10: STD_3 | B10: =TRIG_10_10_24_RawData!E114 -> 0.526 | C10: =AVERAGE(B10,B11) -> 0.539 | D10: =100*(STDEV(B10,B11)/C10) -> 3.4109047 | F10: =C10-$C$4 -> 0.4855 | H10: 150 | K10: Intercept | L10: 0 | O10: 5.2 | P10: 0.2105 | Q10: 71.896552
A11: STD_3 | B11: =TRIG_10_10_24_RawData!E115 -> 0.552
A12: STD_4 | B12: =TRIG_10_10_24_RawData!E116 -> 0.615 | C12: =AVERAGE(B12,B13) -> 0.6155 | D12: =100*(STDEV(B12,B13)/C12) -> 0.11488331 | F12: =C12-$C$4 -> 0.562 | H12: 200
A13: STD_4 | B13: =TRIG_10_10_24_RawData!E117 -> 0.616
A16: Sample Name | B16: Absorbance | C16: Mean | D16: CV | E16: CorrAbs | F16: Final Concentration | G16: Corrected Concentration
A17: GH_Pool | B17: =TRIG_10_10_24_RawData!E88 -> 0.392 | C17: =AVERAGE(B17,B18) -> 0.399 | D17: =100*(STDEV(B17,B18)/C17) -> 2.4810764 | E17: =C17-$C$4 -> 0.3455 | F17: =(E17-$L$10)/$L$9 -> 115.16667 | G17: =F17 -> 115.16667
B18: =TRIG_10_10_24_RawData!E89 -> 0.406
A19: GH_Pool_1:2 | B19: =TRIG_10_10_24_RawData!E90 -> 0.198 | C19: =AVERAGE(B19,B20) -> 0.1945 | D19: =100*(STDEV(B19,B20)/C19) -> 2.5448573 | E19: =C19-$C$4 -> 0.141 | F19: =(E19-$L$10)/$L$9 -> 47 | G19: =F19*2 -> 94
B20: =TRIG_10_10_24_RawData!E91 -> 0.191
A21: GH_Pool_1:4 | B21: =TRIG_10_10_24_RawData!E92 -> 0.114 | C21: =AVERAGE(B21,B22) -> 0.1215 | D21: =100*(STDEV(B21,B22)/C21) -> 8.7297133 | E21: =C21-$C$4 -> 0.068 | F21: =(E21-$L$10)/$L$9 -> 22.666667 | G21: =F21*4 -> 90.666667
B22: =TRIG_10_10_24_RawData!E93 -> 0.129 | H22: Color Scheme: | J22: Overwinter | K22: Greenhouse
A23: GH_Pool_1:8 | B23: =TRIG_10_10_24_RawData!E94 -> 0.083 | C23: 0.083 | D23: =100*(STDEV(B23,B24)/C23) -> 20.446461 | E23: =C23-$C$4 -> 0.0295 | F23: =(E23-$L$10)/$L$9 -> 9.8333333 | G23: =F23*8 -> 78.666667
B24: =TRIG_10_10_24_RawData!E95 -> 0.059
A25: OW_Pool | B25: =TRIG_10_10_24_RawData!E96 -> 0.21 | C25: =AVERAGE(B25,B26) -> 0.209 | D25: =100*(STDEV(B25,B26)/C25) -> 0.67665721 | E25: =C25-$C$4 -> 0.1555 | F25: =(E25-$L$10)/$L$9 -> 51.833333 | G25: =F25 -> 51.833333 | N25: 3
B26: =TRIG_10_10_24_RawData!E97 -> 0.208 | N26: 1
A27: OW_Pool_1:2 | B27: =TRIG_10_10_24_RawData!E98 -> 0.11 | C27: =AVERAGE(B27,B28) -> 0.1085 | D27: =100*(STDEV(B27,B28)/C27) -> 1.955134 | E27: =C27-$C$4 -> 0.055 | F27: =(E27-$L$10)/$L$9 -> 18.333333 | G27: =F27*2 -> 36.666667
B28: =TRIG_10_10_24_RawData!E99 -> 0.107
A29: OW_Pool_1:4 | B29: =TRIG_10_10_24_RawData!E100 -> 0.075 | C29: =AVERAGE(B29,B30) -> 0.077 | D29: =100*(STDEV(B29,B30)/C29) -> 3.673282 | E29: =C29-$C$4 -> 0.0235 | F29: =(E29-$L$10)/$L$9 -> 7.8333333 | G29: =F29*4 -> 31.333333
B30: =TRIG_10_10_24_RawData!E101 -> 0.079
A31: OW_Pool_1:8 | B31: =TRIG_10_10_24_RawData!E102 -> 0.059 | C31: 0.059 | D31: =100*(STDEV(B31,B32)/C31) -> 15.580319 | E31: =C31-$C$4 -> 0.0055 | F31: =(E31-$L$10)/$L$9 -> 1.8333333 | G31: =F31*8 -> 14.666667 | I31: Yellow highlight means did not have enough plasma for duplicate
B32: =TRIG_10_10_24_RawData!E103 -> 0.046
A33: 3.3 | B33: =TRIG_10_10_24_RawData!E104 -> 0.534 | C33: =AVERAGE(B33,B34) -> 0.53 | D33: =100*(STDEV(B33,B34)/C33) -> 1.067331 | E33: =C33-$C$4 -> 0.4765 | F33: =(E33-$L$10)/$L$9 -> 158.83333 | G33: =F33 -> 158.83333
B34: =TRIG_10_10_24_RawData!E105 -> 0.526
A35: 5.2 | B35: =TRIG_10_10_24_RawData!E106 -> 0.267 | C35: =AVERAGE(B35,B36) -> 0.274 | D35: =100*(STDEV(B35,B36)/C35) -> 3.6129544 | E35: =C35-$C$4 -> 0.2205 | F35: =(E35-$L$10)/$L$9 -> 73.5 | G35: =F35 -> 73.5
B36: =TRIG_10_10_24_RawData!E107 -> 0.281
A39: NOTES: | B39: Blank wells not required. S0 serves the same purpose.
B40: No dilution factor required perhaps. Check after doing individuals from 3-month timepoint. Worried GH tortoise will fall off curve.

Sheet TRIG_10_10_24_RawData
A2: Software Version | B2: 2.09.1
A4: Experiment File Path: | B4: E:\GT_Metabolomics\TRIG_10_14_24_Optimization.xpt
A5: Protocol File Path:
A6: Plate Number | B6: Plate 1
A7: Date | B7: 45579
A8: Time | B8: 0.71606481
A9: Reader Type: | B9: Cytation3
A10: Reader Serial Number: | B10: 13081218
A11: Reading Type | B11: Reader
A13: Procedure Details
A14: Plate Type | B14: 96 WELL PLATE
A15: Eject plate on completion
A16: Read | B16: Absorbance Endpoint
B17: Full Plate
B18: Wavelengths: 500
B19: Read Speed: Normal, Delay: 100 msec, Measurements/Data Point: 8
A21: Layout
C23: 1 | D23: 2 | E23: 3 | F23: 4 | G23: 5 | H23: 6 | I23: 7 | J23: 8 | K23: 9 | L23: 10 | M23: 11 | N23: 12
B24: A | C24: STD1 | D24: STD5 | E24: SPL4 | F24: SPL8 | O24: Well ID
C25: 0 | D25: 200 | O25: Conc/Dil
B26: B | C26: STD1 | D26: STD5 | E26: SPL4 | F26: SPL8 | O26: Well ID
C27: 0 | D27: 200 | O27: Conc/Dil
B28: C | C28: STD2 | D28: SPL1 | E28: SPL5 | F28: SPL9 | O28: Well ID
C29: 50 | O29: Conc/Dil
B30: D | C30: STD2 | D30: SPL1 | E30: SPL5 | F30: SPL9 | O30: Well ID
C31: 50 | O31: Conc/Dil
B32: E | C32: STD3 | D32: SPL2 | E32: SPL6 | F32: SPL10 | O32: Well ID
C33: 100 | O33: Conc/Dil
B34: F | C34: STD3 | D34: SPL2 | E34: SPL6 | F34: SPL10 | O34: Well ID
C35: 100 | O35: Conc/Dil
B36: G | C36: STD4 | D36: SPL3 | E36: SPL7 | F36: BLK | O36: Well ID
C37: 150 | O37: Conc/Dil
B38: H | C38: STD4 | D38: SPL3 | E38: SPL7 | F38: BLK | O38: Well ID
C39: 150 | O39: Conc/Dil
A41: 500
A42: Actual Temperature: | B42: 26.1
A43: Actual Temperature: | B43: 26.1
A44: Actual Temperature: | B44: 26.1
A45: Actual Temperature: | B45: 26.1
A46: Actual Temperature: | B46: 26.1
...
